Workbook

Sheet Read me
A1: Roth Conversion Analyzer
A2: Built from Robert Mac Arthur's (KSM) 'IRA analysis.xlsx' framing: convert and pay the tax from outside cash, versus keep the IRA and invest that same outside cash. Extended to answer three questions: Is it worth converting at all? All at once, or over time? And how sensitive is the answer to the assumptions?
A4: HOW TO USE
A5: 1. Change only the blue cells on yellow fill (tab 'Inputs'). Everything else is formulas.
A6: 2. The 'Compare' tab is the answer page: after-tax wealth at your horizon for each strategy, the advantage over not converting, total tax paid, and the year each strategy pulls ahead.
A7: 3. The 'Engine' tab holds six side-by-side strategies (no conversion, all at once, over 3 / 5 / 8 / 10 years). The number of conversion years in each block header is editable, so you can test any spread.
A8: 4. The 'Lump vs None' tab is the CPA's original two-column layout, year by year, with the after-tax value of each side every year so you can see the crossover.
A9: 5. 'Sensitivity' shows the lump-sum advantage across future tax rates and returns, and the break-even future tax rate.
A10: 6. 'RMD & heirs' shows what an unconverted IRA looks like at 75 (required withdrawals) and what the kids keep.
A12: THE FAIR COMPARISON (why this is apples to apples)
A13: Every strategy starts with the same resources: the IRA plus an outside cash pool. A conversion spends pool cash on tax. Not converting leaves that cash in the pool, invested in a taxable account. After-tax wealth each year = Roth (tax-free) + IRA x (1 - future tax rate) + pool (less the deferred tax on its gains). Comparing strategies on after-tax wealth from identical starting resources is the only way the 'all at once vs over time vs never' question is fair.
A15: WHAT THE CPA'S SHEET ASSUMED, AND WHAT THIS ONE ADDS
... A26: Illustrative only, not tax advice. Prepared October 2026 with Claude Code from the KSM worksheet dated the same month.

Sheet Compare
A1: Compare: after-tax wealth by strategy
A2: ="Horizon: "&Inputs!B10&" years (change on Inputs). Start year "&Inputs!B11&", age "&Inputs!B12&" to "&(Inputs!B12+Inputs!B10)&". IRA $"&TEXT(Inputs!B3,"#,##0")&", return "&TEXT(Inputs!B4,"0.0%")&", rate now "&TEXT(Inputs!B5,"0%")&", rate later "&TEXT(Inputs!B6,"0%")&"." -> Horizon: 10 years (change on Inputs). Start year 2026, age 57 to 67. IRA $1,150,000, return 10.0%, rate now 38%, rate later 30%.
A4: Strategy | B4: Conversion years | C4: After-tax wealth at horizon | D4: Advantage vs never ($) | E4: Advantage vs never (%) | F4: Total tax paid (from pool) | G4: Average conversion rate | H4: First year ahead of never | I4: Roth share at horizon
A5: Never convert | B5: =Engine!$F$4 -> 0 | C5: =INDEX(Engine!M7:M47,Inputs!$B$10+1) -> 3689263.9 | D5: =C5-$C$5 -> 0 | E5: =IF($C$5=0,0,D5/$C$5) -> 0 | F5: =Engine!G49 -> 0 | G5: =Engine!F50 -> 0 | H5: =Engine!F51 -> never | I5: =INDEX(Engine!N7:N47,Inputs!$B$10+1) -> 0
A6: All at once | B6: =Engine!$W$4 -> 1 | C6: =INDEX(Engine!AD7:AD47,Inputs!$B$10+1) -> 3669075.8 | D6: =C6-$C$5 -> -20188.097 | E6: =IF($C$5=0,0,D6/$C$5) -> -0.0054721206 | F6: =Engine!X49 -> 437000 | G6: =Engine!W50 -> 0.38 | H6: =Engine!W51 -> 12 | I6: =INDEX(Engine!AE7:AE47,Inputs!$B$10+1) -> 0.78597367
A7: Over 3 years | B7: =Engine!$AN$4 -> 3 | C7: =INDEX(Engine!AU7:AU47,Inputs!$B$10+1) -> 3664891.2 | D7: =C7-$C$5 -> -24372.672 | E7: =IF($C$5=0,0,D7/$C$5) -> -0.0066063782 | F7: =Engine!AO49 -> 482156.67 | G7: =Engine!AN50 -> 0.38 | H7: =Engine!AN51 -> 12 | I7: =INDEX(Engine!AV7:AV47,Inputs!$B$10+1) -> 0.78700074
A8: Over 5 years | B8: =Engine!$BE$4 -> 5 | C8: =INDEX(Engine!BL7:BL47,Inputs!$B$10+1) -> 3660681.1 | D8: =C8-$C$5 -> -28582.773 | E8: =IF($C$5=0,0,D8/$C$5) -> -0.0077475545 | F8: =Engine!BF49 -> 533585.74 | G8: =Engine!BE50 -> 0.38 | H8: =Engine!BE51 -> 13 | I8: =INDEX(Engine!BM7:BM47,Inputs!$B$10+1) -> 0.78803678
A9: Over 8 years | B9: =Engine!$BV$4 -> 8 | C9: =INDEX(Engine!CC7:CC47,Inputs!$B$10+1) -> 3654317.7 | D9: =C9-$C$5 -> -34946.167 | E9: =IF($C$5=0,0,D9/$C$5) -> -0.0094723958 | F9: =Engine!BW49 -> 624685.39 | G9: =Engine!BV50 -> 0.38 | H9: =Engine!BV51 -> 13 | I9: =INDEX(Engine!CD7:CD47,Inputs!$B$10+1) -> 0.7896079
A10: Over 10 years | B10: =Engine!$CM$4 -> 10 | C10: =INDEX(Engine!CT7:CT47,Inputs!$B$10+1) -> 3650043 | D10: =C10-$C$5 -> -39220.851 | E10: =IF($C$5=0,0,D10/$C$5) -> -0.010631078 | F10: =Engine!CN49 -> 696465.46 | G10: =Engine!CM50 -> 0.38 | H10: =Engine!CM51 -> 13 | I10: =INDEX(Engine!CU7:CU47,Inputs!$B$10+1) -> 0.79066684
A12: Best strategy at this horizon: | B12: =INDEX(A5:A10,MATCH(MAX(C5:C10),C5:C10,0)) -> Never convert
A13: Break-even future tax rate (lump sum): | B13: =(Inputs!$B$5*(1+Inputs!$B$4*(1-Inputs!$B$8))^Inputs!$B$10*(1-Inputs!$B$9)+Inputs!$B$5*Inputs!$B$9)/(1+Inputs!$B$4)^Inputs!$B$10 -> 0.30676816 | C13: If your future withdrawal rate is above this, converting all at once beats never converting at this horizon. Below it, keeping the IRA wins. It is lower than the rate you pay now because the taxable pool is taxed along the way.
A15: Fixed horizons (after-tax wealth, $)
A16: Strategy | B16: 5 yrs | C16: 10 yrs | D16: 15 yrs | E16: 20 yrs | F16: 25 yrs | G16: 30 yrs | H16: Age 75 (RMD start)
A17: Never convert | B17: =INDEX(Engine!M7:M47,5+1) -> 2386180.9 | C17: =INDEX(Engine!M7:M47,10+1) -> 3689263.9 | D17: =INDEX(Engine!M7:M47,15+1) -> 5769336.4 | E17: =INDEX(Engine!M7:M47,20+1) -> 9090102.9 | F17: =INDEX(Engine!M7:M47,25+1) -> 14392245 | G17: =INDEX(Engine!M7:M47,30+1) -> 22859007 | H17: =INDEX(Engine!M7:M47,MIN(40,75-Inputs!$B$12)+1) -> 7573282.3
A18: All at once | B18: =INDEX(Engine!AD7:AD47,5+1) -> 2319109.5 | C18: =INDEX(Engine!AD7:AD47,10+1) -> 3669075.8 | D18: =INDEX(Engine!AD7:AD47,15+1) -> 5835257.5 | E18: =INDEX(Engine!AD7:AD47,20+1) -> 9311395.8 | F18: =INDEX(Engine!AD7:AD47,25+1) -> 14890043 | G18: =INDEX(Engine!AD7:AD47,30+1) -> 23843486 | H18: =INDEX(Engine!AD7:AD47,MIN(40,75-Inputs!$B$12)+1) -> 7721425.9
A19: Over 3 years | B19: =INDEX(Engine!AU7:AU47,5+1) -> 2316261.8 | C19: =INDEX(Engine!AU7:AU47,10+1) -> 3664891.2 | D19: =INDEX(Engine!AU7:AU47,15+1) -> 5828968.4 | E19: =INDEX(Engine!AU7:AU47,20+1) -> 9301793.6 | F19: =INDEX(Engine!AU7:AU47,25+1) -> 14875226 | G19: =INDEX(Engine!AU7:AU47,30+1) -> 23820458 | H19: =INDEX(Engine!AU7:AU47,MIN(40,75-Inputs!$B$12)+1) -> 7713331.2
A20: Over 5 years | B20: =INDEX(Engine!BL7:BL47,5+1) -> 2313396.7 | C20: =INDEX(Engine!BL7:BL47,10+1) -> 3660681.1 | D20: =INDEX(Engine!BL7:BL47,15+1) -> 5822640.9 | E20: =INDEX(Engine!BL7:BL47,20+1) -> 9292132.8 | F20: =INDEX(Engine!BL7:BL47,25+1) -> 14860317 | G20: =INDEX(Engine!BL7:BL47,30+1) -> 23797289 | H20: =INDEX(Engine!BL7:BL47,MIN(40,75-Inputs!$B$12)+1) -> 7705187.2
A21: Over 8 years | B21: =INDEX(Engine!CC7:CC47,5+1) -> 2340690.8 | C21: =INDEX(Engine!CC7:CC47,10+1) -> 3654317.7 | D21: =INDEX(Engine!CC7:CC47,15+1) -> 5813077.1 | E21: =INDEX(Engine!CC7:CC47,20+1) -> 9277530.9 | F21: =INDEX(Engine!CC7:CC47,25+1) -> 14837784 | G21: =INDEX(Engine!CC7:CC47,30+1) -> 23762270 | H21: =INDEX(Engine!CC7:CC47,MIN(40,75-Inputs!$B$12)+1) -> 7692877.9
A22: Over 10 years | B22: =INDEX(Engine!CT7:CT47,5+1) -> 2349788.8 | C22: =INDEX(Engine!CT7:CT47,10+1) -> 3650043 | D22: =INDEX(Engine!CT7:CT47,15+1) -> 5806652.5 | E22: =INDEX(Engine!CT7:CT47,20+1) -> 9267721.9 | F22: =INDEX(Engine!CT7:CT47,25+1) -> 14822647 | G22: =INDEX(Engine!CT7:CT47,30+1) -> 23738746 | H22: =INDEX(Engine!CT7:CT47,MIN(40,75-Inputs!$B$12)+1) -> 7684609
A24: Advantage vs never, same horizons ($)
A25: Strategy | B25: 5 yrs | C25: 10 yrs | D25: 15 yrs | E25: 20 yrs | F25: 25 yrs | G25: 30 yrs | H25: Age 75
A26: Never convert | B26: =B17-B$17 -> 0 | C26: =C17-C$17 -> 0 | D26: =D17-D$17 -> 0 | E26: =E17-E$17 -> 0 | F26: =F17-F$17 -> 0 | G26: =G17-G$17 -> 0 | H26: =H17-H$17 -> 0
A27: All at once | B27: =B18-B$17 -> -67071.374 | C27: =C18-C$17 -> -20188.097 | D27: =D18-D$17 -> 65921.137 | E27: =E18-E$17 -> 221292.96 | F27: =F18-F$17 -> 497798.1 | G27: =G18-G$17 -> 984479.06 | H27: =H18-H$17 -> 148143.54
A28: Over 3 years | B28: =B19-B$17 -> -69919.069 | C28: =C19-C$17 -> -24372.672 | D28: =D19-D$17 -> 59631.992 | E28: =E19-E$17 -> 211690.72 | F28: =F19-F$17 -> 482980.25 | G28: =G19-G$17 -> 961450.62 | H28: =H19-H$17 -> 140048.92
A29: Over 5 years | B29: =B20-B$17 -> -72784.134 | C29: =C20-C$17 -> -28582.773 | D29: =D20-D$17 -> 53304.484 | E29: =E20-E$17 -> 202029.91 | F29: =F20-F$17 -> 468072.03 | G29: =G20-G$17 -> 938281.7 | H29: =H20-H$17 -> 131904.92
A30: Over 8 years | B30: =B21-B$17 -> -45490.084 | C30: =C21-C$17 -> -34946.167 | D30: =D21-D$17 -> 43740.716 | E30: =E21-E$17 -> 187427.99 | F30: =F21-F$17 -> 445538.85 | G30: =G21-G$17 -> 903262.84 | H30: =H21-H$17 -> 119595.6
A31: Over 10 years | B31: =B22-B$17 -> -36392.067 | C31: =C22-C$17 -> -39220.851 | D31: =D22-D$17 -> 37316.145 | E31: =E22-E$17 -> 177618.98 | F31: =F22-F$17 -> 430401.93 | G31: =G22-G$17 -> 879738.51 | H31: =H22-H$17 -> 111326.68

Sheet Lump vs None
A1: The CPA's two-column layout, with Joe's inputs and the after-tax value of each side every year
A2: Left: pay the tax from outside cash, convert everything to Roth, let it grow. Right: keep the IRA, invest the same outside cash in a taxable account. Pulled from the Engine (blocks "All at once" and "Never convert").
A4: Year | B4: Age | C4: Calendar | D4: ROTH SIDE: Roth balance | E4: Roth after-tax (no tax due) | F4: IRA SIDE: IRA balance | G4: Tax if withdrawn now | H4: IRA after tax | I4: Taxable pool | J4: Deferred tax on pool gains | K4: IRA side after-tax total | L4: Roth side advantage ($) | M4: Roth side advantage (%)
A5: 0 | B5: =Engine!S7 -> 57 | C5: =Engine!T7 -> 2025 | D5: =Engine!AA7 -> 0 | E5: =D5+Engine!AB7-(Engine!AB7-Engine!AC7)*Inputs!$B$9 -> 764750 | F5: =Engine!I7 -> 1150000 | G5: =-F5*Inputs!$B$6 -> -345000 | H5: =F5+G5 -> 805000 | I5: =Engine!K7 -> 764750 | J5: =-(I5-Engine!L7)*Inputs!$B$9 -> 0 | K5: =H5+I5+J5 -> 1569750 | L5: =E5-K5 -> -805000 | M5: =IF(K5=0,0,L5/K5) -> -0.51282051
A6: 1 | B6: =Engine!S8 -> 58 | C6: =Engine!T8 -> 2026 | D6: =Engine!AA8 -> 1265000 | E6: =D6+Engine!AB8-(Engine!AB8-Engine!AC8)*Inputs!$B$9 -> 1615790.8 | F6: =Engine!I8 -> 1265000 | G6: =-F6*Inputs!$B$6 -> -379500 | H6: =F6+G6 -> 885500 | I6: =Engine!K8 -> 837401.25 | J6: =-(I6-Engine!L8)*Inputs!$B$9 -> -18889.325 | K6: =H6+I6+J6 -> 1704011.9 | L6: =E6-K6 -> -88221.1 | M6: =IF(K6=0,0,L6/K6) -> -0.051772584
A7: 2 | B7: =Engine!S9 -> 59 | C7: =Engine!T9 -> 2027 | D7: =Engine!AA9 -> 1391500 | E7: =D7+Engine!AB9-(Engine!AB9-Engine!AC9)*Inputs!$B$9 -> 1767520.5 | F7: =Engine!I9 -> 1391500 | G7: =-F7*Inputs!$B$6 -> -417450 | H7: =F7+G7 -> 974050 | I7: =Engine!K9 -> 916954.37 | J7: =-(I7-Engine!L9)*Inputs!$B$9 -> -39573.136 | K7: =H7+I7+J7 -> 1851431.2 | L7: =E7-K7 -> -83910.705 | M7: =IF(K7=0,0,L7/K7) -> -0.045322075
A8: 3 | B8: =Engine!S10 -> 60 | C8: =Engine!T10 -> 2028 | D8: =Engine!AA10 -> 1530650 | E8: =D8+Engine!AB10-(Engine!AB10-Engine!AC10)*Inputs!$B$9 -> 1934297.1 | F8: =Engine!I10 -> 1530650 | G8: =-F8*Inputs!$B$6 -> -459195 | H8: =F8+G8 -> 1071455 | I8: =Engine!K10 -> 1004065 | J8: =-(I8-Engine!L10)*Inputs!$B$9 -> -62221.909 | K8: =H8+I8+J8 -> 2013298.1 | L8: =E8-K8 -> -79001.071 | M8: =IF(K8=0,0,L8/K8) -> -0.039239629
A9: 4 | B9: =Engine!S11 -> 61 | C9: =Engine!T11 -> 2029 | D9: =Engine!AA11 -> 1683715 | E9: =D9+Engine!AB11-(Engine!AB11-Engine!AC11)*Inputs!$B$9 -> 2117613.1 | F9: =Engine!I11 -> 1683715 | G9: =-F9*Inputs!$B$6 -> -505114.5 | H9: =F9+G9 -> 1178600.5 | I9: =Engine!K11 -> 1099451.2 | J9: =-(I9-Engine!L11)*Inputs!$B$9 -> -87022.315 | K9: =H9+I9+J9 -> 2191029.4 | L9: =E9-K9 -> -73416.298 | M9: =IF(K9=0,0,L9/K9) -> -0.033507674
A10: 5 | B10: =Engine!S12 -> 62 | C10: =Engine!T12 -> 2030 | D10: =Engine!AA12 -> 1852086.5 | E10: =D10+Engine!AB12-(Engine!AB12-Engine!AC12)*Inputs!$B$9 -> 2319109.5 | F10: =Engine!I12 -> 1852086.5 | G10: =-F10*Inputs!$B$6 -> -555625.95 | H10: =F10+G10 -> 1296460.6 | I10: =Engine!K12 -> 1203899.1 | J10: =-(I10-Engine!L12)*Inputs!$B$9 -> -114178.76 | K10: =H10+I10+J10 -> 2386180.9 | L10: =E10-K10 -> -67071.374 | M10: =IF(K10=0,0,L10/K10) -> -0.028108252
A11: 6 | B11: =Engine!S13 -> 63 | C11: =Engine!T13 -> 2031 | D11: =Engine!AA13 -> 2037295.1 | E11: =D11+Engine!AB13-(Engine!AB13-Engine!AC13)*Inputs!$B$9 -> 2540589.9 | F11: =Engine!I13 -> 2037295.1 | G11: =-F11*Inputs!$B$6 -> -611188.55 | H11: =F11+G11 -> 1426106.6 | I11: =Engine!K13 -> 1318269.5 | J11: =-(I11-Engine!L13)*Inputs!$B$9 -> -143915.07 | K11: =H11+I11+J11 -> 2600461 | L11: =E11-K11 -> -59871.125 | M11: =IF(K11=0,0,L11/K11) -> -0.023023273
A12: 7 | B12: =Engine!S14 -> 64 | C12: =Engine!T14 -> 2032 | D12: =Engine!AA14 -> 2241024.7 | E12: =D12+Engine!AB14-(Engine!AB14-Engine!AC14)*Inputs!$B$9 -> 2784037 | F12: =Engine!I14 -> 2241024.7 | G12: =-F12*Inputs!$B$6 -> -672307.4 | H12: =F12+G12 -> 1568717.3 | I12: =Engine!K14 -> 1443505.1 | J12: =-(I12-Engine!L14)*Inputs!$B$9 -> -176476.32 | K12: =H12+I12+J12 -> 2835746 | L12: =E12-K12 -> -51709.039 | M12: =IF(K12=0,0,L12/K12) -> -0.018234721
A13: 8 | B13: =Engine!S15 -> 65 | C13: =Engine!T15 -> 2033 | D13: =Engine!AA15 -> 2465127.1 | E13: =D13+Engine!AB15-(Engine!AB15-Engine!AC15)*Inputs!$B$9 -> 3051630.2 | F13: =Engine!I15 -> 2465127.1 | G13: =-F13*Inputs!$B$6 -> -739538.14 | H13: =F13+G13 -> 1725589 | I13: =Engine!K15 -> 1580638.1 | J13: =-(I13-Engine!L15)*Inputs!$B$9 -> -212130.9 | K13: =H13+I13+J13 -> 3094096.2 | L13: =E13-K13 -> -42465.961 | M13: =IF(K13=0,0,L13/K13) -> -0.013724835
A14: 9 | B14: =Engine!S16 -> 66 | C14: =Engine!T16 -> 2034 | D14: =Engine!AA16 -> 2711639.8 | E14: =D14+Engine!AB16-(Engine!AB16-Engine!AC16)*Inputs!$B$9 -> 3345765.3 | F14: =Engine!I16 -> 2711639.8 | G14: =-F14*Inputs!$B$6 -> -813491.95 | H14: =F14+G14 -> 1898147.9 | I14: =Engine!K16 -> 1730798.7 | J14: =-(I14-Engine!L16)*Inputs!$B$9 -> -251172.66 | K14: =H14+I14+J14 -> 3377773.9 | L14: =E14-K14 -> -32008.636 | M14: =IF(K14=0,0,L14/K14) -> -0.0094762518
A15: 10 | B15: =Engine!S17 -> 67 | C15: =Engine!T17 -> 2035 | D15: =Engine!AA17 -> 2982803.8 | E15: =D15+Engine!AB17-(Engine!AB17-Engine!AC17)*Inputs!$B$9 -> 3669075.8 | F15: =Engine!I17 -> 2982803.8 | G15: =-F15*Inputs!$B$6 -> -894841.15 | H15: =F15+G15 -> 2087962.7 | I15: =Engine!K17 -> 1895224.6 | J15: =-(I15-Engine!L17)*Inputs!$B$9 -> -293923.39 | K15: =H15+I15+J15 -> 3689263.9 | L15: =E15-K15 -> -20188.097 | M15: =IF(K15=0,0,L15/K15) -> -0.0054721206
A16: 11 | B16: =Engine!S18 -> 68 | C16: =Engine!T18 -> 2036 | D16: =Engine!AA18 -> 3281084.2 | E16: =D16+Engine!AB18-(Engine!AB18-Engine!AC18)*Inputs!$B$9 -> 4024456.6 | F16: =Engine!I18 -> 3281084.2 | G16: =-F16*Inputs!$B$6 -> -984325.26 | H16: =F16+G16 -> 2296758.9 | I16: =Engine!K18 -> 2075270.9 | J16: =-(I16-Engine!L18)*Inputs!$B$9 -> -340735.43 | K16: =H16+I16+J16 -> 4031294.4 | L16: =E16-K16 -> -6837.8604 | M16: =IF(K16=0,0,L16/K16) -> -0.0016961947
... A45: 40 | B45: =Engine!S47 -> 97 | C45: =Engine!T47 -> 2065 | D45: =Engine!AA47 -> 52048144 | E45: =D45+Engine!AB47-(Engine!AB47-Engine!AC47)*Inputs!$B$9 -> 61281633 | F45: =Engine!I47 -> 52048144 | G45: =-F45*Inputs!$B$6 -> -15614443 | H45: =F45+G45 -> 36433701 | I45: =Engine!K47 -> 28845911 | J45: =-(I45-Engine!L47)*Inputs!$B$9 -> -7301101.7 | K45: =H45+I45+J45 -> 57978510 | L45: =E45-K45 -> 3303123.8 | M45: =IF(K45=0,0,L45/K45) -> 0.056971521

Sheet Inputs
A1: Inputs (blue on yellow = change me)
A3: Pre-tax IRA balance today | B3: 1150000 | C3: Joe: own IRA ~$948k + Keli inherited ~$202k (IBKR, Sept 2026). CPA example used $100,000.
A4: Annual return, all accounts | B4: 0.1 | C4: Same investments in IRA, Roth and taxable, as the CPA assumed. 10% = long-run S&P; CPA used 7%.
A5: Default tax rate on conversions (combined federal + NJ) | B5: 0.38 | C5: Used for every year of the schedule below unless you overwrite a year. CPA used 25%.
A6: Tax rate on IRA withdrawals later (combined) | B6: 0.3 | C6: Rate you expect on IRA money when it eventually comes out (RMDs at 75, or earlier draws). Joe retired, single, NJ: ~24% fed + 6.4% NJ. CPA used 25%.
A7: Outside cash pool available for tax | B7: =B3*B5*1.75 -> 764750 | C7: Defaults to 1.75 x the tax on an all-at-once conversion (IRA x default rate x 1.75), enough to cover the slower schedules, which pay more total tax because the IRA keeps growing. Set it to the tax on a lump conversion (IRA x rate) to match the CPA exactly; the comparison between strategies does not change with the pool size as long as no strategy runs short (the Engine flags SHORT). Overwrite with the cash you actually have outside the IRA.
A8: Taxable-account drag (share of return lost to annual tax) | B8: 0.05 | C8: An S&P index fund pays ~1.3% dividends taxed ~30%, so about 4-5% of a 10% return is lost each year. CPA used 25% (return x 0.75). Enter 0.25 to match him.
A9: Capital-gains tax on pool gains at liquidation (combined) | B9: 0.26 | C9: Deferred tax on the taxable pool's unrealized gains when it is finally sold: 20% federal + 3.8% NIIT + NJ ~6.4% at Joe's level. CPA assumed 0. Enter 0 to match him.
A10: Horizon (years) for the Compare tab | B10: 10 | C10: Any whole number 1 to 40. "Update years" here and every tab follows.
A11: Start year | B11: 2026 | C11: Calendar year of the first conversion.
A12: Age at start | B12: 57 | C12: Used for the age column and the RMD tab (RMDs begin at 75).
A13: Heirs' tax rate on an inherited IRA (combined) | B13: 0.35 | C13: Kids must empty an inherited traditional IRA within 10 years and pay ordinary tax; an inherited Roth is tax-free. Rough guess for a working adult child in a high-tax state.
A14: RMD divisor at age 75 (IRS Uniform Lifetime Table) | B14: 24.6 | C14: IRS Publication 590-B, Table III, age 75 = 24.6. Source: irs.gov.
A15: Which conversion-rate schedule to use (A or B) | B15: A | C15: Type A or B. Schedule B is pre-filled with Joe's bracket-managed rates; schedule A is flat at B5. The Engine, Compare and every other tab follow whichever is selected.
A17: Conversion tax rate by year (overwrite any year)
A18: Year # | B18: Calendar | C18: Schedule A: flat (default = B5) | D18: Schedule B: bracket-managed (Joe)
A19: 1 | B19: =Inputs!$B$11+1-1 -> 2026 | C19: =Inputs!$B$5 -> 0.38 | D19: 0.38
A20: 2 | B20: =Inputs!$B$11+2-1 -> 2027 | C20: =Inputs!$B$5 -> 0.38 | D20: 0.38
A21: 3 | B21: =Inputs!$B$11+3-1 -> 2028 | C21: =Inputs!$B$5 -> 0.38 | D21: 0.38
A22: 4 | B22: =Inputs!$B$11+4-1 -> 2029 | C22: =Inputs!$B$5 -> 0.38 | D22: 0.42
A23: 5 | B23: =Inputs!$B$11+5-1 -> 2030 | C23: =Inputs!$B$5 -> 0.38 | D23: 0.42
A24: 6 | B24: =Inputs!$B$11+6-1 -> 2031 | C24: =Inputs!$B$5 -> 0.38 | D24: 0.3
A25: 7 | B25: =Inputs!$B$11+7-1 -> 2032 | C25: =Inputs!$B$5 -> 0.38 | D25: 0.3
A26: 8 | B26: =Inputs!$B$11+8-1 -> 2033 | C26: =Inputs!$B$5 -> 0.38 | D26: 0.3
A27: 9 | B27: =Inputs!$B$11+9-1 -> 2034 | C27: =Inputs!$B$5 -> 0.38 | D27: 0.3
A28: 10 | B28: =Inputs!$B$11+10-1 -> 2035 | C28: =Inputs!$B$5 -> 0.38 | D28: 0.3
A29: 11 | B29: =Inputs!$B$11+11-1 -> 2036 | C29: =Inputs!$B$5 -> 0.38 | D29: 0.3
A30: 12 | B30: =Inputs!$B$11+12-1 -> 2037 | C30: =Inputs!$B$5 -> 0.38 | D30: 0.3
A31: 13 | B31: =Inputs!$B$11+13-1 -> 2038 | C31: =Inputs!$B$5 -> 0.38 | D31: 0.3
A32: 14 | B32: =Inputs!$B$11+14-1 -> 2039 | C32: =Inputs!$B$5 -> 0.38 | D32: 0.3
A33: 15 | B33: =Inputs!$B$11+15-1 -> 2040 | C33: =Inputs!$B$5 -> 0.38 | D33: 0.3
A34: 16 | B34: =Inputs!$B$11+16-1 -> 2041 | C34: =Inputs!$B$5 -> 0.38 | D34: 0.3
A35: 17 | B35: =Inputs!$B$11+17-1 -> 2042 | C35: =Inputs!$B$5 -> 0.38 | D35: 0.3
A36: 18 | B36: =Inputs!$B$11+18-1 -> 2043 | C36: =Inputs!$B$5 -> 0.38 | D36: 0.3
A37: 19 | B37: =Inputs!$B$11+19-1 -> 2044 | C37: =Inputs!$B$5 -> 0.38 | D37: 0.3
A38: 20 | B38: =Inputs!$B$11+20-1 -> 2045 | C38: =Inputs!$B$5 -> 0.38 | D38: 0.3
A39: 21 | B39: =Inputs!$B$11+21-1 -> 2046 | C39: =Inputs!$B$5 -> 0.38 | D39: 0.3
A40: 22 | B40: =Inputs!$B$11+22-1 -> 2047 | C40: =Inputs!$B$5 -> 0.38 | D40: 0.3
A41: 23 | B41: =Inputs!$B$11+23-1 -> 2048 | C41: =Inputs!$B$5 -> 0.38 | D41: 0.3
A42: 24 | B42: =Inputs!$B$11+24-1 -> 2049 | C42: =Inputs!$B$5 -> 0.38 | D42: 0.3
...

Sheet Engine
A1: Engine: six strategies side by side. Each block: conversion years N in the yellow cell (0 = never convert, 1 = all at once). Rows = years 0 to 40.
A2: After-tax wealth = Roth + IRA x (1 - later rate) + Pool - (Pool - Pool basis) x liquidation rate. Pool pays every conversion tax; a red "SHORT" means the pool could not cover it.
A4: Never convert | E4: Conversion years N: | F4: 0 | R4: All at once | V4: Conversion years N: | W4: 1 | AI4: Over 3 years | AM4: Conversion years N: | AN4: 3 | AZ4: Over 5 years | BD4: Conversion years N: | BE4: 5 | BQ4: Over 8 years | BU4: Conversion years N: | BV4: 8 | CH4: Over 10 years | CL4: Conversion years N: | CM4: 10
A6: Yr | B6: Age | C6: Calendar | D6: Rate | E6: IRA begin | F6: Converted | G6: Tax paid | H6: Pool after tax | I6: IRA end | J6: Roth end | K6: Pool end | L6: Pool basis | M6: After-tax wealth | N6: Roth share | O6: Beats never? | P6: Check | R6: Yr | S6: Age | T6: Calendar | U6: Rate | V6: IRA begin | W6: Converted | X6: Tax paid | Y6: Pool after tax | Z6: IRA end | AA6: Roth end | AB6: Pool end | AC6: Pool basis | AD6: After-tax wealth | AE6: Roth share | AF6: Beats never? | AG6: Check | AI6: Yr | AJ6: Age | AK6: Calendar | AL6: Rate | AM6: IRA begin | AN6: Converted | AO6: Tax paid | AP6: Pool after tax | AQ6: IRA end | AR6: Roth end | AS6: Pool end | AT6: Pool basis | AU6: After-tax wealth | AV6: Roth share | AW6: Beats never? | AX6: Check | AZ6: Yr | BA6: Age | BB6: Calendar | BC6: Rate | BD6: IRA begin | BE6: Converted | BF6: Tax paid | BG6: Pool after tax | BH6: IRA end | BI6: Roth end | BJ6: Pool end | BK6: Pool basis | BL6: After-tax wealth | BM6: Roth share | BN6: Beats never? | BO6: Check | BQ6: Yr | BR6: Age | BS6: Calendar | BT6: Rate | BU6: IRA begin | BV6: Converted | BW6: Tax paid | BX6: Pool after tax | BY6: IRA end | BZ6: Roth end | CA6: Pool end | CB6: Pool basis | CC6: After-tax wealth | CD6: Roth share | CE6: Beats never? | CF6: Check | CH6: Yr | CI6: Age | CJ6: Calendar | CK6: Rate | CL6: IRA begin | CM6: Converted | CN6: Tax paid | CO6: Pool after tax | CP6: IRA end | CQ6: Roth end | CR6: Pool end | CS6: Pool basis | CT6: After-tax wealth | CU6: Roth share | CV6: Beats never? | CW6: Check
A7: 0 | B7: =Inputs!$B$12 -> 57 | C7: =Inputs!$B$11-1 -> 2025 | I7: =Inputs!$B$3 -> 1150000 | J7: 0 | K7: =Inputs!$B$7 -> 764750 | L7: =Inputs!$B$7 -> 764750 | M7: =J7+I7*(1-Inputs!$B$6)+K7-(K7-L7)*Inputs!$B$9 -> 1569750 | N7: =IF(M7=0,0,J7/(J7+I7+K7)) -> 0 | R7: 0 | S7: =Inputs!$B$12 -> 57 | T7: =Inputs!$B$11-1 -> 2025 | Z7: =Inputs!$B$3 -> 1150000 | AA7: 0 | AB7: =Inputs!$B$7 -> 764750 | AC7: =Inputs!$B$7 -> 764750 | AD7: =AA7+Z7*(1-Inputs!$B$6)+AB7-(AB7-AC7)*Inputs!$B$9 -> 1569750 | AE7: =IF(AD7=0,0,AA7/(AA7+Z7+AB7)) -> 0 | AI7: 0 | AJ7: =Inputs!$B$12 -> 57 | AK7: =Inputs!$B$11-1 -> 2025 | AQ7: =Inputs!$B$3 -> 1150000 | AR7: 0 | AS7: =Inputs!$B$7 -> 764750 | AT7: =Inputs!$B$7 -> 764750 | AU7: =AR7+AQ7*(1-Inputs!$B$6)+AS7-(AS7-AT7)*Inputs!$B$9 -> 1569750 | AV7: =IF(AU7=0,0,AR7/(AR7+AQ7+AS7)) -> 0 | AZ7: 0 | BA7: =Inputs!$B$12 -> 57 | BB7: =Inputs!$B$11-1 -> 2025 | BH7: =Inputs!$B$3 -> 1150000 | BI7: 0 | BJ7: =Inputs!$B$7 -> 764750 | BK7: =Inputs!$B$7 -> 764750 | BL7: =BI7+BH7*(1-Inputs!$B$6)+BJ7-(BJ7-BK7)*Inputs!$B$9 -> 1569750 | BM7: =IF(BL7=0,0,BI7/(BI7+BH7+BJ7)) -> 0 | BQ7: 0 | BR7: =Inputs!$B$12 -> 57 | BS7: =Inputs!$B$11-1 -> 2025 | BY7: =Inputs!$B$3 -> 1150000 | BZ7: 0 | CA7: =Inputs!$B$7 -> 764750 | CB7: =Inputs!$B$7 -> 764750 | CC7: =BZ7+BY7*(1-Inputs!$B$6)+CA7-(CA7-CB7)*Inputs!$B$9 -> 1569750 | CD7: =IF(CC7=0,0,BZ7/(BZ7+BY7+CA7)) -> 0 | CH7: 0 | CI7: =Inputs!$B$12 -> 57 | CJ7: =Inputs!$B$11-1 -> 2025 | CP7: =Inputs!$B$3 -> 1150000 | CQ7: 0 | CR7: =Inputs!$B$7 -> 764750 | CS7: =Inputs!$B$7 -> 764750 | CT7: =CQ7+CP7*(1-Inputs!$B$6)+CR7-(CR7-CS7)*Inputs!$B$9 -> 1569750 | CU7: =IF(CT7=0,0,CQ7/(CQ7+CP7+CR7)) -> 0
A8: 1 | B8: =B7+1 -> 58 | C8: =C7+1 -> 2026 | D8: =IF(Inputs!$B$15="B",Inputs!$D$19,Inputs!$C$19) -> 0.38 | E8: =I7 -> 1150000 | F8: =IF(A8<=$F$4,E8/($F$4-A8+1),0) -> 0 | G8: =F8*D8 -> 0 | H8: =K7-G8 -> 764750 | I8: =(E8-F8)*(1+Inputs!$B$4) -> 1265000 | J8: =(J7+F8)*(1+Inputs!$B$4) -> 0 | K8: =H8*(1+Inputs!$B$4*(1-Inputs!$B$8)) -> 837401.25 | L8: =IF(K7<=0,0,L7*H8/K7) -> 764750 | M8: =J8+I8*(1-Inputs!$B$6)+K8-(K8-L8)*Inputs!$B$9 -> 1704011.9 | N8: =J8/(J8+I8+K8) -> 0 | O8: =IF(M8>M8,1,0) -> 0 | P8: =IF(H8<0,"SHORT","ok") -> ok | R8: 1 | S8: =S7+1 -> 58 | T8: =T7+1 -> 2026 | U8: =IF(Inputs!$B$15="B",Inputs!$D$19,Inputs!$C$19) -> 0.38 | V8: =Z7 -> 1150000 | W8: =IF(R8<=$W$4,V8/($W$4-R8+1),0) -> 1150000 | X8: =W8*U8 -> 437000 | Y8: =AB7-X8 -> 327750 | Z8: =(V8-W8)*(1+Inputs!$B$4) -> 0 | AA8: =(AA7+W8)*(1+Inputs!$B$4) -> 1265000 | AB8: =Y8*(1+Inputs!$B$4*(1-Inputs!$B$8)) -> 358886.25 | AC8: =IF(AB7<=0,0,AC7*Y8/AB7) -> 327750 | AD8: =AA8+Z8*(1-Inputs!$B$6)+AB8-(AB8-AC8)*Inputs!$B$9 -> 1615790.8 | AE8: =AA8/(AA8+Z8+AB8) -> 0.77899545 | AF8: =IF(AD8>M8,1,0) -> 0 | AG8: =IF(Y8<0,"SHORT","ok") -> ok | AI8: 1 | AJ8: =AJ7+1 -> 58 | AK8: =AK7+1 -> 2026 | AL8: =IF(Inputs!$B$15="B",Inputs!$D$19,Inputs!$C$19) -> 0.38 | AM8: =AQ7 -> 1150000 | AN8: =IF(AI8<=$AN$4,AM8/($AN$4-AI8+1),0) -> 383333.33 | AO8: =AN8*AL8 -> 145666.67 | AP8: =AS7-AO8 -> 619083.33 | AQ8: =(AM8-AN8)*(1+Inputs!$B$4) -> 843333.33 | AR8: =(AR7+AN8)*(1+Inputs!$B$4) -> 421666.67 | AS8: =AP8*(1+Inputs!$B$4*(1-Inputs!$B$8)) -> 677896.25 | AT8: =IF(AS7<=0,0,AT7*AP8/AS7) -> 619083.33 | AU8: =AR8+AQ8*(1-Inputs!$B$6)+AS8-(AS8-AT8)*Inputs!$B$9 -> 1674604.9 | AV8: =AR8/(AR8+AQ8+AS8) -> 0.21702995 | AW8: =IF(AU8>M8,1,0) -> 0 | AX8: =IF(AP8<0,"SHORT","ok") -> ok | AZ8: 1 | BA8: =BA7+1 -> 58 | BB8: =BB7+1 -> 2026 | BC8: =IF(Inputs!$B$15="B",Inputs!$D$19,Inputs!$C$19) -> 0.38 | BD8: =BH7 -> 1150000 | BE8: =IF(AZ8<=$BE$4,BD8/($BE$4-AZ8+1),0) -> 230000 | BF8: =BE8*BC8 -> 87400 | BG8: =BJ7-BF8 -> 677350 | BH8: =(BD8-BE8)*(1+Inputs!$B$4) -> 1012000 | BI8: =(BI7+BE8)*(1+Inputs!$B$4) -> 253000 | BJ8: =BG8*(1+Inputs!$B$4*(1-Inputs!$B$8)) -> 741698.25 | BK8: =IF(BJ7<=0,0,BK7*BG8/BJ7) -> 677350 | BL8: =BI8+BH8*(1-Inputs!$B$6)+BJ8-(BJ8-BK8)*Inputs!$B$9 -> 1686367.7 | BM8: =BI8/(BI8+BH8+BJ8) -> 0.12607775 | BN8: =IF(BL8>M8,1,0) -> 0 | BO8: =IF(BG8<0,"SHORT","ok") -> ok | BQ8: 1 | BR8: =BR7+1 -> 58 | BS8: =BS7+1 -> 2026 | BT8: =IF(Inputs!$B$15="B",Inputs!$D$19,Inputs!$C$19) -> 0.38 | BU8: =BY7 -> 1150000 | BV8: =IF(BQ8<=$BV$4,BU8/($BV$4-BQ8+1),0) -> 143750 | BW8: =BV8*BT8 -> 54625 | BX8: =CA7-BW8 -> 710125 | BY8: =(BU8-BV8)*(1+Inputs!$B$4) -> 1106875 | BZ8: =(BZ7+BV8)*(1+Inputs!$B$4) -> 158125 | CA8: =BX8*(1+Inputs!$B$4*(1-Inputs!$B$8)) -> 777586.88 | CB8: =IF(CA7<=0,0,CB7*BX8/CA7) -> 710125 | CC8: =BZ8+BY8*(1-Inputs!$B$6)+CA8-(CA8-CB8)*Inputs!$B$9 -> 1692984.3 | CD8: =BZ8/(BZ8+BY8+CA8) -> 0.077414088 | CE8: =IF(CC8>M8,1,0) -> 0 | CF8: =IF(BX8<0,"SHORT","ok") -> ok | CH8: 1 | CI8: =CI7+1 -> 58 | CJ8: =CJ7+1 -> 2026 | CK8: =IF(Inputs!$B$15="B",Inputs!$D$19,Inputs!$C$19) -> 0.38 | CL8: =CP7 -> 1150000 | CM8: =IF(CH8<=$CM$4,CL8/($CM$4-CH8+1),0) -> 115000 | CN8: =CM8*CK8 -> 43700 | CO8: =CR7-CN8 -> 721050 | CP8: =(CL8-CM8)*(1+Inputs!$B$4) -> 1138500 | CQ8: =(CQ7+CM8)*(1+Inputs!$B$4) -> 126500 | CR8: =CO8*(1+Inputs!$B$4*(1-Inputs!$B$8)) -> 789549.75 | CS8: =IF(CR7<=0,0,CS7*CO8/CR7) -> 721050 | CT8: =CQ8+CP8*(1-Inputs!$B$6)+CR8-(CR8-CS8)*Inputs!$B$9 -> 1695189.8 | CU8: =CQ8/(CQ8+CP8+CR8) -> 0.061570668 | CV8: =IF(CT8>M8,1,0) -> 0 | CW8: =IF(CO8<0,"SHORT","ok") -> ok
A9: 2 | B9: =B8+1 -> 59 | C9: =C8+1 -> 2027 | D9: =IF(Inputs!$B$15="B",Inputs!$D$20,Inputs!$C$20) -> 0.38 | E9: =I8 -> 1265000 | F9: =IF(A9<=$F$4,E9/($F$4-A9+1),0) -> 0 | G9: =F9*D9 -> 0 | H9: =K8-G9 -> 837401.25 | I9: =(E9-F9)*(1+Inputs!$B$4) -> 1391500 | J9: =(J8+F9)*(1+Inputs!$B$4) -> 0 | K9: =H9*(1+Inputs!$B$4*(1-Inputs!$B$8)) -> 916954.37 | L9: =IF(K8<=0,0,L8*H9/K8) -> 764750 | M9: =J9+I9*(1-Inputs!$B$6)+K9-(K9-L9)*Inputs!$B$9 -> 1851431.2 | N9: =J9/(J9+I9+K9) -> 0 | O9: =IF(M9>M9,1,0) -> 0 | P9: =IF(H9<0,"SHORT","ok") -> ok | R9: 2 | S9: =S8+1 -> 59 | T9: =T8+1 -> 2027 | U9: =IF(Inputs!$B$15="B",Inputs!$D$20,Inputs!$C$20) -> 0.38 | V9: =Z8 -> 0 | W9: =IF(R9<=$W$4,V9/($W$4-R9+1),0) -> 0 | X9: =W9*U9 -> 0 | Y9: =AB8-X9 -> 358886.25 | Z9: =(V9-W9)*(1+Inputs!$B$4) -> 0 | AA9: =(AA8+W9)*(1+Inputs!$B$4) -> 1391500 | AB9: =Y9*(1+Inputs!$B$4*(1-Inputs!$B$8)) -> 392980.44 | AC9: =IF(AB8<=0,0,AC8*Y9/AB8) -> 327750 | AD9: =AA9+Z9*(1-Inputs!$B$6)+AB9-(AB9-AC9)*Inputs!$B$9 -> 1767520.5 | AE9: =AA9/(AA9+Z9+AB9) -> 0.77977879 | AF9: =IF(AD9>M9,1,0) -> 0 | AG9: =IF(Y9<0,"SHORT","ok") -> ok | AI9: 2 | AJ9: =AJ8+1 -> 59 | AK9: =AK8+1 -> 2027 | AL9: =IF(Inputs!$B$15="B",Inputs!$D$20,Inputs!$C$20) -> 0.38 | AM9: =AQ8 -> 843333.33 | AN9: =IF(AI9<=$AN$4,AM9/($AN$4-AI9+1),0) -> 421666.67 | AO9: =AN9*AL9 -> 160233.33 | AP9: =AS8-AO9 -> 517662.92 | AQ9: =(AM9-AN9)*(1+Inputs!$B$4) -> 463833.33 | AR9: =(AR8+AN9)*(1+Inputs!$B$4) -> 927666.67 | AS9: =AP9*(1+Inputs!$B$4*(1-Inputs!$B$8)) -> 566840.89 | AT9: =IF(AS8<=0,0,AT8*AP9/AS8) -> 472751.52 | AU9: =AR9+AQ9*(1-Inputs!$B$6)+AS9-(AS9-AT9)*Inputs!$B$9 -> 1794727.7 | AV9: =AR9/(AR9+AQ9+AS9) -> 0.4737003 | AW9: =IF(AU9>M9,1,0) -> 0 | AX9: =IF(AP9<0,"SHORT","ok") -> ok | AZ9: 2 | BA9: =BA8+1 -> 59 | BB9: =BB8+1 -> 2027 | BC9: =IF(Inputs!$B$15="B",Inputs!$D$20,Inputs!$C$20) -> 0.38 | BD9: =BH8 -> 1012000 | BE9: =IF(AZ9<=$BE$4,BD9/($BE$4-AZ9+1),0) -> 253000 | BF9: =BE9*BC9 -> 96140 | BG9: =BJ8-BF9 -> 645558.25 | BH9: =(BD9-BE9)*(1+Inputs!$B$4) -> 834900 | BI9: =(BI8+BE9)*(1+Inputs!$B$4) -> 556600 | BJ9: =BG9*(1+Inputs!$B$4*(1-Inputs!$B$8)) -> 706886.28 | BK9: =IF(BJ8<=0,0,BK8*BG9/BJ8) -> 589550.91 | BL9: =BI9+BH9*(1-Inputs!$B$6)+BJ9-(BJ9-BK9)*Inputs!$B$9 -> 1817409.1 | BM9: =BI9/(BI9+BH9+BJ9) -> 0.26525145 | BN9: =IF(BL9>M9,1,0) -> 0 | BO9: =IF(BG9<0,"SHORT","ok") -> ok | BQ9: 2 | BR9: =BR8+1 -> 59 | BS9: =BS8+1 -> 2027 | BT9: =IF(Inputs!$B$15="B",Inputs!$D$20,Inputs!$C$20) -> 0.38 | BU9: =BY8 -> 1106875 | BV9: =IF(BQ9<=$BV$4,BU9/($BV$4-BQ9+1),0) -> 158125 | BW9: =BV9*BT9 -> 60087.5 | BX9: =CA8-BW9 -> 717499.38 | BY9: =(BU9-BV9)*(1+Inputs!$B$4) -> 1043625 | BZ9: =(BZ8+BV9)*(1+Inputs!$B$4) -> 347875 | CA9: =BX9*(1+Inputs!$B$4*(1-Inputs!$B$8)) -> 785661.82 | CB9: =IF(CA8<=0,0,CB8*BX9/CA8) -> 655250.57 | CC9: =BZ9+BY9*(1-Inputs!$B$6)+CA9-(CA9-CB9)*Inputs!$B$9 -> 1830167.4 | CD9: =BZ9/(BZ9+BY9+CA9) -> 0.15978371 | CE9: =IF(CC9>M9,1,0) -> 0 | CF9: =IF(BX9<0,"SHORT","ok") -> ok | CH9: 2 | CI9: =CI8+1 -> 59 | CJ9: =CJ8+1 -> 2027 | CK9: =IF(Inputs!$B$15="B",Inputs!$D$20,Inputs!$C$20) -> 0.38 | CL9: =CP8 -> 1138500 | CM9: =IF(CH9<=$CM$4,CL9/($CM$4-CH9+1),0) -> 126500 | CN9: =CM9*CK9 -> 48070 | CO9: =CR8-CN9 -> 741479.75 | CP9: =(CL9-CM9)*(1+Inputs!$B$4) -> 1113200 | CQ9: =(CQ8+CM9)*(1+Inputs!$B$4) -> 278300 | CR9: =CO9*(1+Inputs!$B$4*(1-Inputs!$B$8)) -> 811920.33 | CS9: =IF(CR8<=0,0,CS8*CO9/CR8) -> 677150.46 | CT9: =CQ9+CP9*(1-Inputs!$B$6)+CR9-(CR9-CS9)*Inputs!$B$9 -> 1834420.2 | CU9: =CQ9/(CQ9+CP9+CR9) -> 0.12630364 | CV9: =IF(CT9>M9,1,0) -> 0 | CW9: =IF(CO9<0,"SHORT","ok") -> ok
A10: 3 | B10: =B9+1 -> 60 | C10: =C9+1 -> 2028 | D10: =IF(Inputs!$B$15="B",Inputs!$D$21,Inputs!$C$21) -> 0.38 | E10: =I9 -> 1391500 | F10: =IF(A10<=$F$4,E10/($F$4-A10+1),0) -> 0 | G10: =F10*D10 -> 0 | H10: =K9-G10 -> 916954.37 | I10: =(E10-F10)*(1+Inputs!$B$4) -> 1530650 | J10: =(J9+F10)*(1+Inputs!$B$4) -> 0 | K10: =H10*(1+Inputs!$B$4*(1-Inputs!$B$8)) -> 1004065 | L10: =IF(K9<=0,0,L9*H10/K9) -> 764750 | M10: =J10+I10*(1-Inputs!$B$6)+K10-(K10-L10)*Inputs!$B$9 -> 2013298.1 | N10: =J10/(J10+I10+K10) -> 0 | O10: =IF(M10>M10,1,0) -> 0 | P10: =IF(H10<0,"SHORT","ok") -> ok | R10: 3 | S10: =S9+1 -> 60 | T10: =T9+1 -> 2028 | U10: =IF(Inputs!$B$15="B",Inputs!$D$21,Inputs!$C$21) -> 0.38 | V10: =Z9 -> 0 | W10: =IF(R10<=$W$4,V10/($W$4-R10+1),0) -> 0 | X10: =W10*U10 -> 0 | Y10: =AB9-X10 -> 392980.44 | Z10: =(V10-W10)*(1+Inputs!$B$4) -> 0 | AA10: =(AA9+W10)*(1+Inputs!$B$4) -> 1530650 | AB10: =Y10*(1+Inputs!$B$4*(1-Inputs!$B$8)) -> 430313.59 | AC10: =IF(AB9<=0,0,AC9*Y10/AB9) -> 327750 | AD10: =AA10+Z10*(1-Inputs!$B$6)+AB10-(AB10-AC10)*Inputs!$B$9 -> 1934297.1 | AE10: =AA10/(AA10+Z10+AB10) -> 0.78056013 | AF10: =IF(AD10>M10,1,0) -> 0 | AG10: =IF(Y10<0,"SHORT","ok") -> ok | AI10: 3 | AJ10: =AJ9+1 -> 60 | AK10: =AK9+1 -> 2028 | AL10: =IF(Inputs!$B$15="B",Inputs!$D$21,Inputs!$C$21) -> 0.38 | AM10: =AQ9 -> 463833.33 | AN10: =IF(AI10<=$AN$4,AM10/($AN$4-AI10+1),0) -> 463833.33 | AO10: =AN10*AL10 -> 176256.67 | AP10: =AS9-AO10 -> 390584.23 | AQ10: =(AM10-AN10)*(1+Inputs!$B$4) -> 0 | AR10: =(AR9+AN10)*(1+Inputs!$B$4) -> 1530650 | AS10: =AP10*(1+Inputs!$B$4*(1-Inputs!$B$8)) -> 427689.73 | AT10: =IF(AS9<=0,0,AT9*AP10/AS9) -> 325751.53 | AU10: =AR10+AQ10*(1-Inputs!$B$6)+AS10-(AS10-AT10)*Inputs!$B$9 -> 1931835.8 | AV10: =AR10/(AR10+AQ10+AS10) -> 0.78160596 | AW10: =IF(AU10>M10,1,0) -> 0 | AX10: =IF(AP10<0,"SHORT","ok") -> ok | AZ10: 3 | BA10: =BA9+1 -> 60 | BB10: =BB9+1 -> 2028 | BC10: =IF(Inputs!$B$15="B",Inputs!$D$21,Inputs!$C$21) -> 0.38 | BD10: =BH9 -> 834900 | BE10: =IF(AZ10<=$BE$4,BD10/($BE$4-AZ10+1),0) -> 278300 | BF10: =BE10*BC10 -> 105754 | BG10: =BJ9-BF10 -> 601132.28 | BH10: =(BD10-BE10)*(1+Inputs!$B$4) -> 612260 | BI10: =(BI9+BE10)*(1+Inputs!$B$4) -> 918390 | BJ10: =BG10*(1+Inputs!$B$4*(1-Inputs!$B$8)) -> 658239.85 | BK10: =IF(BJ9<=0,0,BK9*BG10/BJ9) -> 501350.92 | BL10: =BI10+BH10*(1-Inputs!$B$6)+BJ10-(BJ10-BK10)*Inputs!$B$9 -> 1964420.7 | BM10: =BI10/(BI10+BH10+BJ10) -> 0.41956885 | BN10: =IF(BL10>M10,1,0) -> 0 | BO10: =IF(BG10<0,"SHORT","ok") -> ok | BQ10: 3 | BR10: =BR9+1 -> 60 | BS10: =BS9+1 -> 2028 | BT10: =IF(Inputs!$B$15="B",Inputs!$D$21,Inputs!$C$21) -> 0.38 | BU10: =BY9 -> 1043625 | BV10: =IF(BQ10<=$BV$4,BU10/($BV$4-BQ10+1),0) -> 173937.5 | BW10: =BV10*BT10 -> 66096.25 | BX10: =CA9-BW10 -> 719565.57 | BY10: =(BU10-BV10)*(1+Inputs!$B$4) -> 956656.25 | BZ10: =(BZ9+BV10)*(1+Inputs!$B$4) -> 573993.75 | CA10: =BX10*(1+Inputs!$B$4*(1-Inputs!$B$8)) -> 787924.29 | CB10: =IF(CA9<=0,0,CB9*BX10/CA9) -> 600125.57 | CC10: =BZ10+BY10*(1-Inputs!$B$6)+CA10-(CA10-CB10)*Inputs!$B$9 -> 1982749.8 | CD10: =BZ10/(BZ10+BY10+CA10) -> 0.24756323 | CE10: =IF(CC10>M10,1,0) -> 0 | CF10: =IF(BX10<0,"SHORT","ok") -> ok | CH10: 3 | CI10: =CI9+1 -> 60 | CJ10: =CJ9+1 -> 2028 | CK10: =IF(Inputs!$B$15="B",Inputs!$D$21,Inputs!$C$21) -> 0.38 | CL10: =CP9 -> 1113200 | CM10: =IF(CH10<=$CM$4,CL10/($CM$4-CH10+1),0) -> 139150 | CN10: =CM10*CK10 -> 52877 | CO10: =CR9-CN10 -> 759043.33 | CP10: =(CL10-CM10)*(1+Inputs!$B$4) -> 1071455 | CQ10: =(CQ9+CM10)*(1+Inputs!$B$4) -> 459195 | CR10: =CO10*(1+Inputs!$B$4*(1-Inputs!$B$8)) -> 831152.44 | CS10: =IF(CR9<=0,0,CS9*CO10/CR9) -> 633050.46 | CT10: =CQ10+CP10*(1-Inputs!$B$6)+CR10-(CR10-CS10)*Inputs!$B$9 -> 1988859.4 | CU10: =CQ10/(CQ10+CP10+CR10) -> 0.19442566 | CV10: =IF(CT10>M10,1,0) -> 0 | CW10: =IF(CO10<0,"SHORT","ok") -> ok
A11: 4 | B11: =B10+1 -> 61 | C11: =C10+1 -> 2029 | D11: =IF(Inputs!$B$15="B",Inputs!$D$22,Inputs!$C$22) -> 0.38 | E11: =I10 -> 1530650 | F11: =IF(A11<=$F$4,E11/($F$4-A11+1),0) -> 0 | G11: =F11*D11 -> 0 | H11: =K10-G11 -> 1004065 | I11: =(E11-F11)*(1+Inputs!$B$4) -> 1683715 | J11: =(J10+F11)*(1+Inputs!$B$4) -> 0 | K11: =H11*(1+Inputs!$B$4*(1-Inputs!$B$8)) -> 1099451.2 | L11: =IF(K10<=0,0,L10*H11/K10) -> 764750 | M11: =J11+I11*(1-Inputs!$B$6)+K11-(K11-L11)*Inputs!$B$9 -> 2191029.4 | N11: =J11/(J11+I11+K11) -> 0 | O11: =IF(M11>M11,1,0) -> 0 | P11: =IF(H11<0,"SHORT","ok") -> ok | R11: 4 | S11: =S10+1 -> 61 | T11: =T10+1 -> 2029 | U11: =IF(Inputs!$B$15="B",Inputs!$D$22,Inputs!$C$22) -> 0.38 | V11: =Z10 -> 0 | W11: =IF(R11<=$W$4,V11/($W$4-R11+1),0) -> 0 | X11: =W11*U11 -> 0 | Y11: =AB10-X11 -> 430313.59 | Z11: =(V11-W11)*(1+Inputs!$B$4) -> 0 | AA11: =(AA10+W11)*(1+Inputs!$B$4) -> 1683715 | AB11: =Y11*(1+Inputs!$B$4*(1-Inputs!$B$8)) -> 471193.38 | AC11: =IF(AB10<=0,0,AC10*Y11/AB10) -> 327750 | AD11: =AA11+Z11*(1-Inputs!$B$6)+AB11-(AB11-AC11)*Inputs!$B$9 -> 2117613.1 | AE11: =AA11/(AA11+Z11+AB11) -> 0.78133948 | AF11: =IF(AD11>M11,1,0) -> 0 | AG11: =IF(Y11<0,"SHORT","ok") -> ok | AI11: 4 | AJ11: =AJ10+1 -> 61 | AK11: =AK10+1 -> 2029 | AL11: =IF(Inputs!$B$15="B",Inputs!$D$22,Inputs!$C$22) -> 0.38 | AM11: =AQ10 -> 0 | AN11: =IF(AI11<=$AN$4,AM11/($AN$4-AI11+1),0) -> 0 | AO11: =AN11*AL11 -> 0 | AP11: =AS10-AO11 -> 427689.73 | AQ11: =(AM11-AN11)*(1+Inputs!$B$4) -> 0 | AR11: =(AR10+AN11)*(1+Inputs!$B$4) -> 1683715 | AS11: =AP11*(1+Inputs!$B$4*(1-Inputs!$B$8)) -> 468320.25 | AT11: =IF(AS10<=0,0,AT10*AP11/AS10) -> 325751.53 | AU11: =AR11+AQ11*(1-Inputs!$B$6)+AS11-(AS11-AT11)*Inputs!$B$9 -> 2114967.4 | AV11: =AR11/(AR11+AQ11+AS11) -> 0.78238263 | AW11: =IF(AU11>M11,1,0) -> 0 | AX11: =IF(AP11<0,"SHORT","ok") -> ok | AZ11: 4 | BA11: =BA10+1 -> 61 | BB11: =BB10+1 -> 2029 | BC11: =IF(Inputs!$B$15="B",Inputs!$D$22,Inputs!$C$22) -> 0.38 | BD11: =BH10 -> 612260 | BE11: =IF(AZ11<=$BE$4,BD11/($BE$4-AZ11+1),0) -> 306130 | BF11: =BE11*BC11 -> 116329.4 | BG11: =BJ10-BF11 -> 541910.45 | BH11: =(BD11-BE11)*(1+Inputs!$B$4) -> 336743 | BI11: =(BI10+BE11)*(1+Inputs!$B$4) -> 1346972 | BJ11: =BG11*(1+Inputs!$B$4*(1-Inputs!$B$8)) -> 593391.94 | BK11: =IF(BJ10<=0,0,BK10*BG11/BJ10) -> 412748.18 | BL11: =BI11+BH11*(1-Inputs!$B$6)+BJ11-(BJ11-BK11)*Inputs!$B$9 -> 2129116.7 | BM11: =BI11/(BI11+BH11+BJ11) -> 0.59152777 | BN11: =IF(BL11>M11,1,0) -> 0 | BO11: =IF(BG11<0,"SHORT","ok") -> ok | BQ11: 4 | BR11: =BR10+1 -> 61 | BS11: =BS10+1 -> 2029 | BT11: =IF(Inputs!$B$15="B",Inputs!$D$22,Inputs!$C$22) -> 0.38 | BU11: =BY10 -> 956656.25 | BV11: =IF(BQ11<=$BV$4,BU11/($BV$4-BQ11+1),0) -> 191331.25 | BW11: =BV11*BT11 -> 72705.875 | BX11: =CA10-BW11 -> 715218.42 | BY11: =(BU11-BV11)*(1+Inputs!$B$4) -> 841857.5 | BZ11: =(BZ10+BV11)*(1+Inputs!$B$4) -> 841857.5 | CA11: =BX11*(1+Inputs!$B$4*(1-Inputs!$B$8)) -> 783164.17 | CB11: =IF(CA10<=0,0,CB10*BX11/CA10) -> 544748.86 | CC11: =BZ11+BY11*(1-Inputs!$B$6)+CA11-(CA11-CB11)*Inputs!$B$9 -> 2152333.9 | CD11: =BZ11/(BZ11+BY11+CA11) -> 0.34126418 | CE11: =IF(CC11>M11,1,0) -> 0 | CF11: =IF(BX11<0,"SHORT","ok") -> ok | CH11: 4 | CI11: =CI10+1 -> 61 | CJ11: =CJ10+1 -> 2029 | CK11: =IF(Inputs!$B$15="B",Inputs!$D$22,Inputs!$C$22) -> 0.38 | CL11: =CP10 -> 1071455 | CM11: =IF(CH11<=$CM$4,CL11/($CM$4-CH11+1),0) -> 153065 | CN11: =CM11*CK11 -> 58164.7 | CO11: =CR10-CN11 -> 772987.74 | CP11: =(CL11-CM11)*(1+Inputs!$B$4) -> 1010229 | CQ11: =(CQ10+CM11)*(1+Inputs!$B$4) -> 673486 | CR11: =CO11*(1+Inputs!$B$4*(1-Inputs!$B$8)) -> 846421.58 | CS11: =IF(CR10<=0,0,CS10*CO11/CR10) -> 588749.09 | CT11: =CQ11+CP11*(1-Inputs!$B$6)+CR11-(CR11-CS11)*Inputs!$B$9 -> 2160073 | CU11: =CQ11/(CQ11+CP11+CR11) -> 0.26618563 | CV11: =IF(CT11>M11,1,0) -> 0 | CW11: =IF(CO11<0,"SHORT","ok") -> ok
A12: 5 | B12: =B11+1 -> 62 | C12: =C11+1 -> 2030 | D12: =IF(Inputs!$B$15="B",Inputs!$D$23,Inputs!$C$23) -> 0.38 | E12: =I11 -> 1683715 | F12: =IF(A12<=$F$4,E12/($F$4-A12+1),0) -> 0 | G12: =F12*D12 -> 0 | H12: =K11-G12 -> 1099451.2 | I12: =(E12-F12)*(1+Inputs!$B$4) -> 1852086.5 | J12: =(J11+F12)*(1+Inputs!$B$4) -> 0 | K12: =H12*(1+Inputs!$B$4*(1-Inputs!$B$8)) -> 1203899.1 | L12: =IF(K11<=0,0,L11*H12/K11) -> 764750 | M12: =J12+I12*(1-Inputs!$B$6)+K12-(K12-L12)*Inputs!$B$9 -> 2386180.9 | N12: =J12/(J12+I12+K12) -> 0 | O12: =IF(M12>M12,1,0) -> 0 | P12: =IF(H12<0,"SHORT","ok") -> ok | R12: 5 | S12: =S11+1 -> 62 | T12: =T11+1 -> 2030 | U12: =IF(Inputs!$B$15="B",Inputs!$D$23,Inputs!$C$23) -> 0.38 | V12: =Z11 -> 0 | W12: =IF(R12<=$W$4,V12/($W$4-R12+1),0) -> 0 | X12: =W12*U12 -> 0 | Y12: =AB11-X12 -> 471193.38 | Z12: =(V12-W12)*(1+Inputs!$B$4) -> 0 | AA12: =(AA11+W12)*(1+Inputs!$B$4) -> 1852086.5 | AB12: =Y12*(1+Inputs!$B$4*(1-Inputs!$B$8)) -> 515956.75 | AC12: =IF(AB11<=0,0,AC11*Y12/AB11) -> 327750 | AD12: =AA12+Z12*(1-Inputs!$B$6)+AB12-(AB12-AC12)*Inputs!$B$9 -> 2319109.5 | AE12: =AA12/(AA12+Z12+AB12) -> 0.78211684 | AF12: =IF(AD12>M12,1,0) -> 0 | AG12: =IF(Y12<0,"SHORT","ok") -> ok | AI12: 5 | AJ12: =AJ11+1 -> 62 | AK12: =AK11+1 -> 2030 | AL12: =IF(Inputs!$B$15="B",Inputs!$D$23,Inputs!$C$23) -> 0.38 | AM12: =AQ11 -> 0 | AN12: =IF(AI12<=$AN$4,AM12/($AN$4-AI12+1),0) -> 0 | AO12: =AN12*AL12 -> 0 | AP12: =AS11-AO12 -> 468320.25 | AQ12: =(AM12-AN12)*(1+Inputs!$B$4) -> 0 | AR12: =(AR11+AN12)*(1+Inputs!$B$4) -> 1852086.5 | AS12: =AP12*(1+Inputs!$B$4*(1-Inputs!$B$8)) -> 512810.68 | AT12: =IF(AS11<=0,0,AT11*AP12/AS11) -> 325751.53 | AU12: =AR12+AQ12*(1-Inputs!$B$6)+AS12-(AS12-AT12)*Inputs!$B$9 -> 2316261.8 | AV12: =AR12/(AR12+AQ12+AS12) -> 0.78315731 | AW12: =IF(AU12>M12,1,0) -> 0 | AX12: =IF(AP12<0,"SHORT","ok") -> ok | AZ12: 5 | BA12: =BA11+1 -> 62 | BB12: =BB11+1 -> 2030 | BC12: =IF(Inputs!$B$15="B",Inputs!$D$23,Inputs!$C$23) -> 0.38 | BD12: =BH11 -> 336743 | BE12: =IF(AZ12<=$BE$4,BD12/($BE$4-AZ12+1),0) -> 336743 | BF12: =BE12*BC12 -> 127962.34 | BG12: =BJ11-BF12 -> 465429.6 | BH12: =(BD12-BE12)*(1+Inputs!$B$4) -> 0 | BI12: =(BI11+BE12)*(1+Inputs!$B$4) -> 1852086.5 | BJ12: =BG12*(1+Inputs!$B$4*(1-Inputs!$B$8)) -> 509645.42 | BK12: =IF(BJ11<=0,0,BK11*BG12/BJ11) -> 323740.87 | BL12: =BI12+BH12*(1-Inputs!$B$6)+BJ12-(BJ12-BK12)*Inputs!$B$9 -> 2313396.7 | BM12: =BI12/(BI12+BH12+BJ12) -> 0.78420692 | BN12: =IF(BL12>M12,1,0) -> 0 | BO12: =IF(BG12<0,"SHORT","ok") -> ok | BQ12: 5 | BR12: =BR11+1 -> 62 | BS12: =BS11+1 -> 2030 | BT12: =IF(Inputs!$B$15="B",Inputs!$D$23,Inputs!$C$23) -> 0.38 | BU12: =BY11 -> 841857.5 | BV12: =IF(BQ12<=$BV$4,BU12/($BV$4-BQ12+1),0) -> 210464.38 | BW12: =BV12*BT12 -> 79976.462 | BX12: =CA11-BW12 -> 703187.71 | BY12: =(BU12-BV12)*(1+Inputs!$B$4) -> 694532.44 | BZ12: =(BZ11+BV12)*(1+Inputs!$B$4) -> 1157554.1 | CA12: =BX12*(1+Inputs!$B$4*(1-Inputs!$B$8)) -> 769990.54 | CB12: =IF(CA11<=0,0,CB11*BX12/CA11) -> 489119.29 | CC12: =BZ12+BY12*(1-Inputs!$B$6)+CA12-(CA12-CB12)*Inputs!$B$9 -> 2340690.8 | CD12: =BZ12/(BZ12+BY12+CA12) -> 0.44146455 | CE12: =IF(CC12>M12,1,0) -> 0 | CF12: =IF(BX12<0,"SHORT","ok") -> ok | CH12: 5 | CI12: =CI11+1 -> 62 | CJ12: =CJ11+1 -> 2030 | CK12: =IF(Inputs!$B$15="B",Inputs!$D$23,Inputs!$C$23) -> 0.38 | CL12: =CP11 -> 1010229 | CM12: =IF(CH12<=$CM$4,CL12/($CM$4-CH12+1),0) -> 168371.5 | CN12: =CM12*CK12 -> 63981.17 | CO12: =CR11-CN12 -> 782440.41 | CP12: =(CL12-CM12)*(1+Inputs!$B$4) -> 926043.25 | CQ12: =(CQ11+CM12)*(1+Inputs!$B$4) -> 926043.25 | CR12: =CO12*(1+Inputs!$B$4*(1-Inputs!$B$8)) -> 856772.25 | CS12: =IF(CR11<=0,0,CS11*CO12/CR11) -> 544245.43 | CT12: =CQ12+CP12*(1-Inputs!$B$6)+CR12-(CR12-CS12)*Inputs!$B$9 -> 2349788.8 | CU12: =CQ12/(CQ12+CP12+CR12) -> 0.34185734 | CV12: =IF(CT12>M12,1,0) -> 0 | CW12: =IF(CO12<0,"SHORT","ok") -> ok
A13: 6 | B13: =B12+1 -> 63 | C13: =C12+1 -> 2031 | D13: =IF(Inputs!$B$15="B",Inputs!$D$24,Inputs!$C$24) -> 0.38 | E13: =I12 -> 1852086.5 | F13: =IF(A13<=$F$4,E13/($F$4-A13+1),0) -> 0 | G13: =F13*D13 -> 0 | H13: =K12-G13 -> 1203899.1 | I13: =(E13-F13)*(1+Inputs!$B$4) -> 2037295.1 | J13: =(J12+F13)*(1+Inputs!$B$4) -> 0 | K13: =H13*(1+Inputs!$B$4*(1-Inputs!$B$8)) -> 1318269.5 | L13: =IF(K12<=0,0,L12*H13/K12) -> 764750 | M13: =J13+I13*(1-Inputs!$B$6)+K13-(K13-L13)*Inputs!$B$9 -> 2600461 | N13: =J13/(J13+I13+K13) -> 0 | O13: =IF(M13>M13,1,0) -> 0 | P13: =IF(H13<0,"SHORT","ok") -> ok | R13: 6 | S13: =S12+1 -> 63 | T13: =T12+1 -> 2031 | U13: =IF(Inputs!$B$15="B",Inputs!$D$24,Inputs!$C$24) -> 0.38 | V13: =Z12 -> 0 | W13: =IF(R13<=$W$4,V13/($W$4-R13+1),0) -> 0 | X13: =W13*U13 -> 0 | Y13: =AB12-X13 -> 515956.75 | Z13: =(V13-W13)*(1+Inputs!$B$4) -> 0 | AA13: =(AA12+W13)*(1+Inputs!$B$4) -> 2037295.1 | AB13: =Y13*(1+Inputs!$B$4*(1-Inputs!$B$8)) -> 564972.64 | AC13: =IF(AB12<=0,0,AC12*Y13/AB12) -> 327750 | AD13: =AA13+Z13*(1-Inputs!$B$6)+AB13-(AB13-AC13)*Inputs!$B$9 -> 2540589.9 | AE13: =AA13/(AA13+Z13+AB13) -> 0.7828922 | AF13: =IF(AD13>M13,1,0) -> 0 | AG13: =IF(Y13<0,"SHORT","ok") -> ok | AI13: 6 | AJ13: =AJ12+1 -> 63 | AK13: =AK12+1 -> 2031 | AL13: =IF(Inputs!$B$15="B",Inputs!$D$24,Inputs!$C$24) -> 0.38 | AM13: =AQ12 -> 0 | AN13: =IF(AI13<=$AN$4,AM13/($AN$4-AI13+1),0) -> 0 | AO13: =AN13*AL13 -> 0 | AP13: =AS12-AO13 -> 512810.68 | AQ13: =(AM13-AN13)*(1+Inputs!$B$4) -> 0 | AR13: =(AR12+AN13)*(1+Inputs!$B$4) -> 2037295.1 | AS13: =AP13*(1+Inputs!$B$4*(1-Inputs!$B$8)) -> 561527.69 | AT13: =IF(AS12<=0,0,AT12*AP13/AS12) -> 325751.53 | AU13: =AR13+AQ13*(1-Inputs!$B$6)+AS13-(AS13-AT13)*Inputs!$B$9 -> 2537521 | AV13: =AR13/(AR13+AQ13+AS13) -> 0.78392998 | AW13: =IF(AU13>M13,1,0) -> 0 | AX13: =IF(AP13<0,"SHORT","ok") -> ok | AZ13: 6 | BA13: =BA12+1 -> 63 | BB13: =BB12+1 -> 2031 | BC13: =IF(Inputs!$B$15="B",Inputs!$D$24,Inputs!$C$24) -> 0.38 | BD13: =BH12 -> 0 | BE13: =IF(AZ13<=$BE$4,BD13/($BE$4-AZ13+1),0) -> 0 | BF13: =BE13*BC13 -> 0 | BG13: =BJ12-BF13 -> 509645.42 | BH13: =(BD13-BE13)*(1+Inputs!$B$4) -> 0 | BI13: =(BI12+BE13)*(1+Inputs!$B$4) -> 2037295.1 | BJ13: =BG13*(1+Inputs!$B$4*(1-Inputs!$B$8)) -> 558061.73 | BK13: =IF(BJ12<=0,0,BK12*BG13/BJ12) -> 323740.87 | BL13: =BI13+BH13*(1-Inputs!$B$6)+BJ13-(BJ13-BK13)*Inputs!$B$9 -> 2534433.5 | BM13: =BI13/(BI13+BH13+BJ13) -> 0.78497688 | BN13: =IF(BL13>M13,1,0) -> 0 | BO13: =IF(BG13<0,"SHORT","ok") -> ok | BQ13: 6 | BR13: =BR12+1 -> 63 | BS13: =BS12+1 -> 2031 | BT13: =IF(Inputs!$B$15="B",Inputs!$D$24,Inputs!$C$24) -> 0.38 | BU13: =BY12 -> 694532.44 | BV13: =IF(BQ13<=$BV$4,BU13/($BV$4-BQ13+1),0) -> 231510.81 | BW13: =BV13*BT13 -> 87974.109 | BX13: =CA12-BW13 -> 682016.43 | BY13: =(BU13-BV13)*(1+Inputs!$B$4) -> 509323.79 | BZ13: =(BZ12+BV13)*(1+Inputs!$B$4) -> 1527971.4 | CA13: =BX13*(1+Inputs!$B$4*(1-Inputs!$B$8)) -> 746807.99 | CB13: =IF(CA12<=0,0,CB12*BX13/CA12) -> 433235.7 | CC13: =BZ13+BY13*(1-Inputs!$B$6)+CA13-(CA13-CB13)*Inputs!$B$9 -> 2549777.2 | CD13: =BZ13/(BZ13+BY13+CA13) -> 0.54881996 | CE13: =IF(CC13>M13,1,0) -> 0 | CF13: =IF(BX13<0,"SHORT","ok") -> ok | CH13: 6 | CI13: =CI12+1 -> 63 | CJ13: =CJ12+1 -> 2031 | CK13: =IF(Inputs!$B$15="B",Inputs!$D$24,Inputs!$C$24) -> 0.38 | CL13: =CP12 -> 926043.25 | CM13: =IF(CH13<=$CM$4,CL13/($CM$4-CH13+1),0) -> 185208.65 | CN13: =CM13*CK13 -> 70379.287 | CO13: =CR12-CN13 -> 786392.96 | CP13: =(CL13-CM13)*(1+Inputs!$B$4) -> 814918.06 | CQ13: =(CQ12+CM13)*(1+Inputs!$B$4) -> 1222377.1 | CR13: =CO13*(1+Inputs!$B$4*(1-Inputs!$B$8)) -> 861100.29 | CS13: =IF(CR12<=0,0,CS12*CO13/CR12) -> 499538.56 | CT13: =CQ13+CP13*(1-Inputs!$B$6)+CR13-(CR13-CS13)*Inputs!$B$9 -> 2559914 | CU13: =CQ13/(CQ13+CP13+CR13) -> 0.42174269 | CV13: =IF(CT13>M13,1,0) -> 0 | CW13: =IF(CO13<0,"SHORT","ok") -> ok
A14: 7 | B14: =B13+1 -> 64 | C14: =C13+1 -> 2032 | D14: =IF(Inputs!$B$15="B",Inputs!$D$25,Inputs!$C$25) -> 0.38 | E14: =I13 -> 2037295.1 | F14: =IF(A14<=$F$4,E14/($F$4-A14+1),0) -> 0 | G14: =F14*D14 -> 0 | H14: =K13-G14 -> 1318269.5 | I14: =(E14-F14)*(1+Inputs!$B$4) -> 2241024.7 | J14: =(J13+F14)*(1+Inputs!$B$4) -> 0 | K14: =H14*(1+Inputs!$B$4*(1-Inputs!$B$8)) -> 1443505.1 | L14: =IF(K13<=0,0,L13*H14/K13) -> 764750 | M14: =J14+I14*(1-Inputs!$B$6)+K14-(K14-L14)*Inputs!$B$9 -> 2835746 | N14: =J14/(J14+I14+K14) -> 0 | O14: =IF(M14>M14,1,0) -> 0 | P14: =IF(H14<0,"SHORT","ok") -> ok | R14: 7 | S14: =S13+1 -> 64 | T14: =T13+1 -> 2032 | U14: =IF(Inputs!$B$15="B",Inputs!$D$25,Inputs!$C$25) -> 0.38 | V14: =Z13 -> 0 | W14: =IF(R14<=$W$4,V14/($W$4-R14+1),0) -> 0 | X14: =W14*U14 -> 0 | Y14: =AB13-X14 -> 564972.64 | Z14: =(V14-W14)*(1+Inputs!$B$4) -> 0 | AA14: =(AA13+W14)*(1+Inputs!$B$4) -> 2241024.7 | AB14: =Y14*(1+Inputs!$B$4*(1-Inputs!$B$8)) -> 618645.04 | AC14: =IF(AB13<=0,0,AC13*Y14/AB13) -> 327750 | AD14: =AA14+Z14*(1-Inputs!$B$6)+AB14-(AB14-AC14)*Inputs!$B$9 -> 2784037 | AE14: =AA14/(AA14+Z14+AB14) -> 0.78366556 | AF14: =IF(AD14>M14,1,0) -> 0 | AG14: =IF(Y14<0,"SHORT","ok") -> ok | AI14: 7 | AJ14: =AJ13+1 -> 64 | AK14: =AK13+1 -> 2032 | AL14: =IF(Inputs!$B$15="B",Inputs!$D$25,Inputs!$C$25) -> 0.38 | AM14: =AQ13 -> 0 | AN14: =IF(AI14<=$AN$4,AM14/($AN$4-AI14+1),0) -> 0 | AO14: =AN14*AL14 -> 0 | AP14: =AS13-AO14 -> 561527.69 | AQ14: =(AM14-AN14)*(1+Inputs!$B$4) -> 0 | AR14: =(AR13+AN14)*(1+Inputs!$B$4) -> 2241024.7 | AS14: =AP14*(1+Inputs!$B$4*(1-Inputs!$B$8)) -> 614872.82 | AT14: =IF(AS13<=0,0,AT13*AP14/AS13) -> 325751.53 | AU14: =AR14+AQ14*(1-Inputs!$B$6)+AS14-(AS14-AT14)*Inputs!$B$9 -> 2780726 | AV14: =AR14/(AR14+AQ14+AS14) -> 0.78470067 | AW14: =IF(AU14>M14,1,0) -> 0 | AX14: =IF(AP14<0,"SHORT","ok") -> ok | AZ14: 7 | BA14: =BA13+1 -> 64 | BB14: =BB13+1 -> 2032 | BC14: =IF(Inputs!$B$15="B",Inputs!$D$25,Inputs!$C$25) -> 0.38 | BD14: =BH13 -> 0 | BE14: =IF(AZ14<=$BE$4,BD14/($BE$4-AZ14+1),0) -> 0 | BF14: =BE14*BC14 -> 0 | BG14: =BJ13-BF14 -> 558061.73 | BH14: =(BD14-BE14)*(1+Inputs!$B$4) -> 0 | BI14: =(BI13+BE14)*(1+Inputs!$B$4) -> 2241024.7 | BJ14: =BG14*(1+Inputs!$B$4*(1-Inputs!$B$8)) -> 611077.59 | BK14: =IF(BJ13<=0,0,BK13*BG14/BJ13) -> 323740.87 | BL14: =BI14+BH14*(1-Inputs!$B$6)+BJ14-(BJ14-BK14)*Inputs!$B$9 -> 2777394.7 | BM14: =BI14/(BI14+BH14+BJ14) -> 0.78574485 | BN14: =IF(BL14>M14,1,0) -> 0 | BO14: =IF(BG14<0,"SHORT","ok") -> ok | BQ14: 7 | BR14: =BR13+1 -> 64 | BS14: =BS13+1 -> 2032 | BT14: =IF(Inputs!$B$15="B",Inputs!$D$25,Inputs!$C$25) -> 0.38 | BU14: =BY13 -> 509323.79 | BV14: =IF(BQ14<=$BV$4,BU14/($BV$4-BQ14+1),0) -> 254661.89 | BW14: =BV14*BT14 -> 96771.52 | BX14: =CA13-BW14 -> 650036.47 | BY14: =(BU14-BV14)*(1+Inputs!$B$4) -> 280128.08 | BZ14: =(BZ13+BV14)*(1+Inputs!$B$4) -> 1960896.6 | CA14: =BX14*(1+Inputs!$B$4*(1-Inputs!$B$8)) -> 711789.94 | CB14: =IF(CA13<=0,0,CB13*BX14/CA13) -> 377096.94 | CC14: =BZ14+BY14*(1-Inputs!$B$6)+CA14-(CA14-CB14)*Inputs!$B$9 -> 2781756 | CD14: =BZ14/(BZ14+BY14+CA14) -> 0.66407711 | CE14: =IF(CC14>M14,1,0) -> 0 | CF14: =IF(BX14<0,"SHORT","ok") -> ok | CH14: 7 | CI14: =CI13+1 -> 64 | CJ14: =CJ13+1 -> 2032 | CK14: =IF(Inputs!$B$15="B",Inputs!$D$25,Inputs!$C$25) -> 0.38 | CL14: =CP13 -> 814918.06 | CM14: =IF(CH14<=$CM$4,CL14/($CM$4-CH14+1),0) -> 203729.52 | CN14: =CM14*CK14 -> 77417.216 | CO14: =CR13-CN14 -> 783683.07 | CP14: =(CL14-CM14)*(1+Inputs!$B$4) -> 672307.4 | CQ14: =(CQ13+CM14)*(1+Inputs!$B$4) -> 1568717.3 | CR14: =CO14*(1+Inputs!$B$4*(1-Inputs!$B$8)) -> 858132.97 | CS14: =IF(CR13<=0,0,CS13*CO14/CR13) -> 454627.55 | CT14: =CQ14+CP14*(1-Inputs!$B$6)+CR14-(CR14-CS14)*Inputs!$B$9 -> 2792554 | CU14: =CQ14/(CQ14+CP14+CR14) -> 0.50617537 | CV14: =IF(CT14>M14,1,0) -> 0 | CW14: =IF(CO14<0,"SHORT","ok") -> ok
A15: 8 | B15: =B14+1 -> 65 | C15: =C14+1 -> 2033 | D15: =IF(Inputs!$B$15="B",Inputs!$D$26,Inputs!$C$26) -> 0.38 | E15: =I14 -> 2241024.7 | F15: =IF(A15<=$F$4,E15/($F$4-A15+1),0) -> 0 | G15: =F15*D15 -> 0 | H15: =K14-G15 -> 1443505.1 | I15: =(E15-F15)*(1+Inputs!$B$4) -> 2465127.1 | J15: =(J14+F15)*(1+Inputs!$B$4) -> 0 | K15: =H15*(1+Inputs!$B$4*(1-Inputs!$B$8)) -> 1580638.1 | L15: =IF(K14<=0,0,L14*H15/K14) -> 764750 | M15: =J15+I15*(1-Inputs!$B$6)+K15-(K15-L15)*Inputs!$B$9 -> 3094096.2 | N15: =J15/(J15+I15+K15) -> 0 | O15: =IF(M15>M15,1,0) -> 0 | P15: =IF(H15<0,"SHORT","ok") -> ok | R15: 8 | S15: =S14+1 -> 65 | T15: =T14+1 -> 2033 | U15: =IF(Inputs!$B$15="B",Inputs!$D$26,Inputs!$C$26) -> 0.38 | V15: =Z14 -> 0 | W15: =IF(R15<=$W$4,V15/($W$4-R15+1),0) -> 0 | X15: =W15*U15 -> 0 | Y15: =AB14-X15 -> 618645.04 | Z15: =(V15-W15)*(1+Inputs!$B$4) -> 0 | AA15: =(AA14+W15)*(1+Inputs!$B$4) -> 2465127.1 | AB15: =Y15*(1+Inputs!$B$4*(1-Inputs!$B$8)) -> 677416.32 | AC15: =IF(AB14<=0,0,AC14*Y15/AB14) -> 327750 | AD15: =AA15+Z15*(1-Inputs!$B$6)+AB15-(AB15-AC15)*Inputs!$B$9 -> 3051630.2 | AE15: =AA15/(AA15+Z15+AB15) -> 0.78443693 | AF15: =IF(AD15>M15,1,0) -> 0 | AG15: =IF(Y15<0,"SHORT","ok") -> ok | AI15: 8 | AJ15: =AJ14+1 -> 65 | AK15: =AK14+1 -> 2033 | AL15: =IF(Inputs!$B$15="B",Inputs!$D$26,Inputs!$C$26) -> 0.38 | AM15: =AQ14 -> 0 | AN15: =IF(AI15<=$AN$4,AM15/($AN$4-AI15+1),0) -> 0 | AO15: =AN15*AL15 -> 0 | AP15: =AS14-AO15 -> 614872.82 | AQ15: =(AM15-AN15)*(1+Inputs!$B$4) -> 0 | AR15: =(AR14+AN15)*(1+Inputs!$B$4) -> 2465127.1 | AS15: =AP15*(1+Inputs!$B$4*(1-Inputs!$B$8)) -> 673285.74 | AT15: =IF(AS14<=0,0,AT14*AP15/AS14) -> 325751.53 | AU15: =AR15+AQ15*(1-Inputs!$B$6)+AS15-(AS15-AT15)*Inputs!$B$9 -> 3048054 | AV15: =AR15/(AR15+AQ15+AS15) -> 0.78546935 | AW15: =IF(AU15>M15,1,0) -> 0 | AX15: =IF(AP15<0,"SHORT","ok") -> ok | AZ15: 8 | BA15: =BA14+1 -> 65 | BB15: =BB14+1 -> 2033 | BC15: =IF(Inputs!$B$15="B",Inputs!$D$26,Inputs!$C$26) -> 0.38 | BD15: =BH14 -> 0 | BE15: =IF(AZ15<=$BE$4,BD15/($BE$4-AZ15+1),0) -> 0 | BF15: =BE15*BC15 -> 0 | BG15: =BJ14-BF15 -> 611077.59 | BH15: =(BD15-BE15)*(1+Inputs!$B$4) -> 0 | BI15: =(BI14+BE15)*(1+Inputs!$B$4) -> 2465127.1 | BJ15: =BG15*(1+Inputs!$B$4*(1-Inputs!$B$8)) -> 669129.97 | BK15: =IF(BJ14<=0,0,BK14*BG15/BJ14) -> 323740.87 | BL15: =BI15+BH15*(1-Inputs!$B$6)+BJ15-(BJ15-BK15)*Inputs!$B$9 -> 3044455.9 | BM15: =BI15/(BI15+BH15+BJ15) -> 0.78651082 | BN15: =IF(BL15>M15,1,0) -> 0 | BO15: =IF(BG15<0,"SHORT","ok") -> ok | BQ15: 8 | BR15: =BR14+1 -> 65 | BS15: =BS14+1 -> 2033 | BT15: =IF(Inputs!$B$15="B",Inputs!$D$26,Inputs!$C$26) -> 0.38 | BU15: =BY14 -> 280128.08 | BV15: =IF(BQ15<=$BV$4,BU15/($BV$4-BQ15+1),0) -> 280128.08 | BW15: =BV15*BT15 -> 106448.67 | BX15: =CA14-BW15 -> 605341.26 | BY15: =(BU15-BV15)*(1+Inputs!$B$4) -> 0 | BZ15: =(BZ14+BV15)*(1+Inputs!$B$4) -> 2465127.1 | CA15: =BX15*(1+Inputs!$B$4*(1-Inputs!$B$8)) -> 662848.68 | CB15: =IF(CA14<=0,0,CB14*BX15/CA14) -> 320701.84 | CC15: =BZ15+BY15*(1-Inputs!$B$6)+CA15-(CA15-CB15)*Inputs!$B$9 -> 3039017.6 | CD15: =BZ15/(BZ15+BY15+CA15) -> 0.78809021 | CE15: =IF(CC15>M15,1,0) -> 0 | CF15: =IF(BX15<0,"SHORT","ok") -> ok | CH15: 8 | CI15: =CI14+1 -> 65 | CJ15: =CJ14+1 -> 2033 | CK15: =IF(Inputs!$B$15="B",Inputs!$D$26,Inputs!$C$26) -> 0.38 | CL15: =CP14 -> 672307.4 | CM15: =IF(CH15<=$CM$4,CL15/($CM$4-CH15+1),0) -> 224102.47 | CN15: =CM15*CK15 -> 85158.937 | CO15: =CR14-CN15 -> 772974.03 | CP15: =(CL15-CM15)*(1+Inputs!$B$4) -> 493025.43 | CQ15: =(CQ14+CM15)*(1+Inputs!$B$4) -> 1972101.7 | CR15: =CO15*(1+Inputs!$B$4*(1-Inputs!$B$8)) -> 846406.56 | CS15: =IF(CR14<=0,0,CS14*CO15/CR14) -> 409511.47 | CT15: =CQ15+CP15*(1-Inputs!$B$6)+CR15-(CR15-CS15)*Inputs!$B$9 -> 3050033.3 | CU15: =CQ15/(CQ15+CP15+CR15) -> 0.59552518 | CV15: =IF(CT15>M15,1,0) -> 0 | CW15: =IF(CO15<0,"SHORT","ok") -> ok
A16: 9 | B16: =B15+1 -> 66 | C16: =C15+1 -> 2034 | D16: =IF(Inputs!$B$15="B",Inputs!$D$27,Inputs!$C$27) -> 0.38 | E16: =I15 -> 2465127.1 | F16: =IF(A16<=$F$4,E16/($F$4-A16+1),0) -> 0 | G16: =F16*D16 -> 0 | H16: =K15-G16 -> 1580638.1 | I16: =(E16-F16)*(1+Inputs!$B$4) -> 2711639.8 | J16: =(J15+F16)*(1+Inputs!$B$4) -> 0 | K16: =H16*(1+Inputs!$B$4*(1-Inputs!$B$8)) -> 1730798.7 | L16: =IF(K15<=0,0,L15*H16/K15) -> 764750 | M16: =J16+I16*(1-Inputs!$B$6)+K16-(K16-L16)*Inputs!$B$9 -> 3377773.9 | N16: =J16/(J16+I16+K16) -> 0 | O16: =IF(M16>M16,1,0) -> 0 | P16: =IF(H16<0,"SHORT","ok") -> ok | R16: 9 | S16: =S15+1 -> 66 | T16: =T15+1 -> 2034 | U16: =IF(Inputs!$B$15="B",Inputs!$D$27,Inputs!$C$27) -> 0.38 | V16: =Z15 -> 0 | W16: =IF(R16<=$W$4,V16/($W$4-R16+1),0) -> 0 | X16: =W16*U16 -> 0 | Y16: =AB15-X16 -> 677416.32 | Z16: =(V16-W16)*(1+Inputs!$B$4) -> 0 | AA16: =(AA15+W16)*(1+Inputs!$B$4) -> 2711639.8 | AB16: =Y16*(1+Inputs!$B$4*(1-Inputs!$B$8)) -> 741770.87 | AC16: =IF(AB15<=0,0,AC15*Y16/AB15) -> 327750 | AD16: =AA16+Z16*(1-Inputs!$B$6)+AB16-(AB16-AC16)*Inputs!$B$9 -> 3345765.3 | AE16: =AA16/(AA16+Z16+AB16) -> 0.7852063 | AF16: =IF(AD16>M16,1,0) -> 0 | AG16: =IF(Y16<0,"SHORT","ok") -> ok | AI16: 9 | AJ16: =AJ15+1 -> 66 | AK16: =AK15+1 -> 2034 | AL16: =IF(Inputs!$B$15="B",Inputs!$D$27,Inputs!$C$27) -> 0.38 | AM16: =AQ15 -> 0 | AN16: =IF(AI16<=$AN$4,AM16/($AN$4-AI16+1),0) -> 0 | AO16: =AN16*AL16 -> 0 | AP16: =AS15-AO16 -> 673285.74 | AQ16: =(AM16-AN16)*(1+Inputs!$B$4) -> 0 | AR16: =(AR15+AN16)*(1+Inputs!$B$4) -> 2711639.8 | AS16: =AP16*(1+Inputs!$B$4*(1-Inputs!$B$8)) -> 737247.89 | AT16: =IF(AS15<=0,0,AT15*AP16/AS15) -> 325751.53 | AU16: =AR16+AQ16*(1-Inputs!$B$6)+AS16-(AS16-AT16)*Inputs!$B$9 -> 3341898.7 | AV16: =AR16/(AR16+AQ16+AS16) -> 0.78623604 | AW16: =IF(AU16>M16,1,0) -> 0 | AX16: =IF(AP16<0,"SHORT","ok") -> ok | AZ16: 9 | BA16: =BA15+1 -> 66 | BB16: =BB15+1 -> 2034 | BC16: =IF(Inputs!$B$15="B",Inputs!$D$27,Inputs!$C$27) -> 0.38 | BD16: =BH15 -> 0 | BE16: =IF(AZ16<=$BE$4,BD16/($BE$4-AZ16+1),0) -> 0 | BF16: =BE16*BC16 -> 0 | BG16: =BJ15-BF16 -> 669129.97 | BH16: =(BD16-BE16)*(1+Inputs!$B$4) -> 0 | BI16: =(BI15+BE16)*(1+Inputs!$B$4) -> 2711639.8 | BJ16: =BG16*(1+Inputs!$B$4*(1-Inputs!$B$8)) -> 732697.31 | BK16: =IF(BJ15<=0,0,BK15*BG16/BJ15) -> 323740.87 | BL16: =BI16+BH16*(1-Inputs!$B$6)+BJ16-(BJ16-BK16)*Inputs!$B$9 -> 3338008.5 | BM16: =BI16/(BI16+BH16+BJ16) -> 0.7872748 | BN16: =IF(BL16>M16,1,0) -> 0 | BO16: =IF(BG16<0,"SHORT","ok") -> ok | BQ16: 9 | BR16: =BR15+1 -> 66 | BS16: =BS15+1 -> 2034 | BT16: =IF(Inputs!$B$15="B",Inputs!$D$27,Inputs!$C$27) -> 0.38 | BU16: =BY15 -> 0 | BV16: =IF(BQ16<=$BV$4,BU16/($BV$4-BQ16+1),0) -> 0 | BW16: =BV16*BT16 -> 0 | BX16: =CA15-BW16 -> 662848.68 | BY16: =(BU16-BV16)*(1+Inputs!$B$4) -> 0 | BZ16: =(BZ15+BV16)*(1+Inputs!$B$4) -> 2711639.8 | CA16: =BX16*(1+Inputs!$B$4*(1-Inputs!$B$8)) -> 725819.31 | CB16: =IF(CA15<=0,0,CB15*BX16/CA15) -> 320701.84 | CC16: =BZ16+BY16*(1-Inputs!$B$6)+CA16-(CA16-CB16)*Inputs!$B$9 -> 3332128.6 | CD16: =BZ16/(BZ16+BY16+CA16) -> 0.78885006 | CE16: =IF(CC16>M16,1,0) -> 0 | CF16: =IF(BX16<0,"SHORT","ok") -> ok | CH16: 9 | CI16: =CI15+1 -> 66 | CJ16: =CJ15+1 -> 2034 | CK16: =IF(Inputs!$B$15="B",Inputs!$D$27,Inputs!$C$27) -> 0.38 | CL16: =CP15 -> 493025.43 | CM16: =IF(CH16<=$CM$4,CL16/($CM$4-CH16+1),0) -> 246512.71 | CN16: =CM16*CK16 -> 93674.831 | CO16: =CR15-CN16 -> 752731.73 | CP16: =(CL16-CM16)*(1+Inputs!$B$4) -> 271163.98 | CQ16: =(CQ15+CM16)*(1+Inputs!$B$4) -> 2440475.9 | CR16: =CO16*(1+Inputs!$B$4*(1-Inputs!$B$8)) -> 824241.25 | CS16: =IF(CR15<=0,0,CS15*CO16/CR15) -> 364189.37 | CT16: =CQ16+CP16*(1-Inputs!$B$6)+CR16-(CR16-CS16)*Inputs!$B$9 -> 3334918.4 | CU16: =CQ16/(CQ16+CP16+CR16) -> 0.69020303 | CV16: =IF(CT16>M16,1,0) -> 0 | CW16: =IF(CO16<0,"SHORT","ok") -> ok
