Workbook

Sheet Holdings
A1: Rank | B1: Ticker | C1: Company | D1: GICS Sector | E1: Sub-Industry | F1: Weight | G1: Cumulative Weight | H1: Price ($) | I1: P/E (TTM) | J1: EPS (TTM) | K1: Mkt Cap ($B) | L1: Price/Sales | M1: Revenue TTM ($B) | N1: Notes
A2: 1 | B2: ETN | C2: Eaton Corporation plc | D2: Industrials | E2: Specialty Industrial Machinery | F2: 0.084408 | G2: =SUM($F$2:F2) -> 0.084408 | H2: 438.76 | I2: 44.6803 | J2: 9.82 | K2: 170.4144 | L2: 5.6756 | M2: =IF(AND(N(K2)>0,N(L2)>0),K2/L2,"") -> 30.025795
A3: 2 | B3: PWR | C3: Quanta Services, Inc. | D3: Industrials | E3: Engineering & Construction | F3: 0.081208 | G3: =SUM($F$2:F3) -> 0.165616 | H3: 634.9 | I3: 72.643 | J3: 8.74 | K3: 95.453 | L3: 2.9009 | M3: =IF(AND(N(K3)>0,N(L3)>0),K3/L3,"") -> 32.904616
A4: 3 | B4: GEV | C4: GE Vernova Inc. | D4: Industrials | E4: Specialty Industrial Machinery | F4: 0.079108 | G4: =SUM($F$2:F4) -> 0.244724 | H4: 951.82 | I4: 27.2884 | J4: 34.88 | K4: 253.5016 | L4: 6.1281 | M4: =IF(AND(N(K4)>0,N(L4)>0),K4/L4,"") -> 41.36708
A5: 4 | B5: VRT | C5: Vertiv Holdings Co | D5: Industrials | E5: Electrical Equipment & Parts | F5: 0.065007 | G5: =SUM($F$2:F5) -> 0.309731 | H5: 248.78 | I5: 55.7803 | J5: 4.46 | K5: 95.7774 | L5: 8.3433 | M5: =IF(AND(N(K5)>0,N(L5)>0),K5/L5,"") -> 11.479558
A6: 5 | B6: BE | C6: Bloom Energy Corporation | D6: Industrials | E6: Electrical Equipment & Parts | F6: 0.051705 | G6: =SUM($F$2:F6) -> 0.361436 | H6: 275.19 | I6: 357.3896 | J6: 0.77 | K6: 81.051 | L6: 26.035 | M6: =IF(AND(N(K6)>0,N(L6)>0),K6/L6,"") -> 3.1131554
A7: 6 | B7: GOOGL | C7: Alphabet Inc. | D7: Communication Services | E7: Internet Content & Information | F7: 0.042004 | G7: =SUM($F$2:F7) -> 0.40344 | H7: 337.83 | I7: 16.9338 | J7: 19.95 | K7: 4131.6387 | L7: 9.2665 | M7: =IF(AND(N(K7)>0,N(L7)>0),K7/L7,"") -> 445.86831
A8: 7 | B8: NVDA | C8: NVIDIA Corporation | D8: Information Technology | E8: Semiconductors | F8: 0.040504 | G8: =SUM($F$2:F8) -> 0.443944 | H8: 225.51 | I8: 28.9115 | J8: 7.8 | K8: 5445.3899 | L8: 17.9734 | M8: =IF(AND(N(K8)>0,N(L8)>0),K8/L8,"") -> 302.96938
A9: 8 | B9: AVGO | C9: Broadcom Inc. | D9: Information Technology | E9: Semiconductors | F9: 0.039504 | G9: =SUM($F$2:F9) -> 0.483448 | H9: 354.99 | I9: 45.3372 | J9: 7.83 | K9: 1694.5908 | L9: 19.0181 | M9: =IF(AND(N(K9)>0,N(L9)>0),K9/L9,"") -> 89.104106
A10: 9 | B10: CCJ | C10: Cameco Corporation | D10: Energy | E10: Uranium | F10: 0.035604 | G10: =SUM($F$2:F10) -> 0.519052 | H10: 90.8 | K10: 39.5464 | M10: =IF(AND(N(K10)>0,N(L10)>0),K10/L10,"") | N10: ADR: Yahoo mixes USD price with CAD earnings; P/E, EPS, P/S blanked
A11: 10 | B11: CEG | C11: Constellation Energy Corporation | D11: Utilities | E11: Utilities - Independent Power Producers | F11: 0.030503 | G11: =SUM($F$2:F11) -> 0.549555 | H11: 263.88 | I11: 25.7695 | J11: 10.24 | K11: 93.4946 | L11: 2.9899 | M11: =IF(AND(N(K11)>0,N(L11)>0),K11/L11,"") -> 31.270143
A12: 11 | B12: AMD | C12: Advanced Micro Devices, Inc. | D12: Information Technology | E12: Semiconductors | F12: 0.027503 | G12: =SUM($F$2:F12) -> 0.577058 | H12: 614.61 | I12: 156.3893 | J12: 3.93 | K12: 1003.3355 | L12: 24.2909 | M12: =IF(AND(N(K12)>0,N(L12)>0),K12/L12,"") -> 41.304995
A13: 12 | B13: NVT | C13: nVent Electric plc | D13: Industrials | E13: Electrical Equipment & Parts | F13: 0.019902 | G13: =SUM($F$2:F13) -> 0.59696 | H13: 162.85 | I13: 45.3621 | J13: 3.59 | K13: 26.3586 | L13: 5.4527 | M13: =IF(AND(N(K13)>0,N(L13)>0),K13/L13,"") -> 4.8340455
A14: 13 | B14: HUBB | C14: Hubbell Incorporated | D14: Industrials | E14: Electrical Equipment & Parts | F14: 0.018302 | G14: =SUM($F$2:F14) -> 0.615262 | H14: 463.7 | I14: 27.4704 | J14: 16.88 | K14: 24.4985 | L14: 3.9364 | M14: =IF(AND(N(K14)>0,N(L14)>0),K14/L14,"") -> 6.2235799
A15: 14 | B15: VST | C15: Vistra Corp. | D15: Utilities | E15: Utilities - Independent Power Producers | F15: 0.015802 | G15: =SUM($F$2:F15) -> 0.631064 | H15: 137.97 | I15: 23.7062 | J15: 5.82 | K15: 46.3076 | L15: 2.4103 | M15: =IF(AND(N(K15)>0,N(L15)>0),K15/L15,"") -> 19.21238
A16: 15 | B16: D | C16: Dominion Energy, Inc. | D16: Utilities | E16: Utilities - Regulated Electric | F16: 0.015402 | G16: =SUM($F$2:F16) -> 0.646466 | H16: 61.17 | I16: 21.3136 | J16: 2.87 | K16: 53.8006 | L16: 2.9693 | M16: =IF(AND(N(K16)>0,N(L16)>0),K16/L16,"") -> 18.118951
A17: 16 | B17: XEL | C17: Xcel Energy Inc. | D17: Utilities | E17: Utilities - Regulated Electric | F17: 0.014701 | G17: =SUM($F$2:F17) -> 0.661167 | H17: 70.66 | I17: 19.306 | J17: 3.66 | K17: 44.1367 | L17: 3.0197 | M17: =IF(AND(N(K17)>0,N(L17)>0),K17/L17,"") -> 14.616253
A18: 17 | B18: STRL | C18: Sterling Infrastructure, Inc. | D18: Industrials | E18: Engineering & Construction | F18: 0.012001 | G18: =SUM($F$2:F18) -> 0.673168 | H18: 512 | I18: 36.5714 | J18: 14 | K18: 15.6613 | L18: 4.5547 | M18: =IF(AND(N(K18)>0,N(L18)>0),K18/L18,"") -> 3.4384921
A19: 18 | B19: GNRC | C19: Generac Holdings Inc. | D19: Industrials | E19: Specialty Industrial Machinery | F19: 0.011401 | G19: =SUM($F$2:F19) -> 0.684569 | H19: 199.42 | I19: 45.6339 | J19: 4.37 | K19: 11.7785 | L19: 2.6536 | M19: =IF(AND(N(K19)>0,N(L19)>0),K19/L19,"") -> 4.4386871
A20: 19 | B20: MTZ | C20: MasTec, Inc. | D20: Industrials | E20: Engineering & Construction | F20: 0.011101 | G20: =SUM($F$2:F20) -> 0.69567 | H20: 217.52 | I20: 34.6922 | J20: 6.27 | K20: 17.4679 | L20: 1.0844 | M20: =IF(AND(N(K20)>0,N(L20)>0),K20/L20,"") -> 16.108355
A21: 20 | B21: BWXT | C21: BWX Technologies, Inc. | D21: Industrials | E21: Aerospace & Defense | F21: 0.011001 | G21: =SUM($F$2:F21) -> 0.706671 | H21: 141.81 | I21: 37.4169 | J21: 3.79 | K21: 12.9929 | L21: 3.6975 | M21: =IF(AND(N(K21)>0,N(L21)>0),K21/L21,"") -> 3.5139689
A22: 21 | B22: PEG | C22: Public Service Enterprise Group Incorporated | D22: Utilities | E22: Utilities - Regulated Electric | F22: 0.010901 | G22: =SUM($F$2:F22) -> 0.717572 | H22: 67.31 | I22: 16.7438 | J22: 4.02 | K22: 33.5487 | L22: 2.6747 | M22: =IF(AND(N(K22)>0,N(L22)>0),K22/L22,"") -> 12.542977
... A25: 24 | B25: MRVL | C25: Marvell Technology, Inc. | D25: Information Technology | E25: Semiconductors | F25: 0.008501 | G25: =SUM($F$2:F25) -> 0.743875 | H25: 260.9 | I25: 86.9667 | J25: 3 | K25: 234.472 | L25: 24.8111 | M25: =IF(AND(N(K25)>0,N(L25)>0),K25/L25,"") -> 9.4502864
A26: 25 | B26: NXE | C26: NexGen Energy Ltd. | D26: Energy | E26: Uranium | F26: 0.007601 | G26: =SUM($F$2:F26) -> 0.751476 | H26: 9.63 | K26: 6.457 | M26: =IF(AND(N(K26)>0,N(L26)>0),K26/L26,"") | N26: ADR: Yahoo mixes USD price with CAD earnings; P/E, EPS, P/S blanked
A27: 26 | B27: VMI | C27: Valmont Industries, Inc. | D27: Industrials | E27: Conglomerates | F27: 0.007201 | G27: =SUM($F$2:F27) -> 0.758677 | H27: 471.01 | I27: 18.2845 | J27: 25.76 | K27: 9.0928 | L27: 2.1485 | M27: =IF(AND(N(K27)>0,N(L27)>0),K27/L27,"") -> 4.232162
A28: 27 | B28: OKLO | C28: Oklo Inc. | D28: Utilities | E28: Utilities - Independent Power Producers | F28: 0.007001 | G28: =SUM($F$2:F28) -> 0.765678 | H28: 38.82 | J28: -0.9 | K28: 7.2212 | L28: 5967.938 | M28: =IF(AND(N(K28)>0,N(L28)>0),K28/L28,"") -> 0.0012099992 | N28: Negative trailing EPS; P/E blank
A29: 28 | B29: ENS | C29: EnerSys | D29: Industrials | E29: Electrical Equipment & Parts | F29: 0.006901 | G29: =SUM($F$2:F29) -> 0.772579 | H29: 179.49 | I29: 19.2586 | J29: 9.32 | K29: 6.4733 | L29: 1.7062 | M29: =IF(AND(N(K29)>0,N(L29)>0),K29/L29,"") -> 3.7939866
A30: 29 | B30: EVRG | C30: Evergy, Inc. | D30: Utilities | E30: Utilities - Regulated Electric | F30: 0.005701 | G30: =SUM($F$2:F30) -> 0.77828 | H30: 78.42 | I30: 19.9542 | J30: 3.93 | K30: 18.0811 | L30: 2.9671 | M30: =IF(AND(N(K30)>0,N(L30)>0),K30/L30,"") -> 6.0938627
A31: 30 | B31: DY | C31: Dycom Industries, Inc. | D31: Industrials | E31: Engineering & Construction | F31: 0.005601 | G31: =SUM($F$2:F31) -> 0.783881 | H31: 280.94 | I31: 25.6801 | J31: 10.94 | K31: 8.4734 | L31: 1.2316 | M31: =IF(AND(N(K31)>0,N(L31)>0),K31/L31,"") -> 6.8799935
A32: 31 | B32: ARM | C32: Arm Holdings plc | D32: Information Technology | E32: Semiconductors | F32: 0.005401 | G32: =SUM($F$2:F32) -> 0.789282 | H32: 332.56 | I32: 342.8453 | J32: 0.97 | K32: 355.1736 | L32: 68.8855 | M32: =IF(AND(N(K32)>0,N(L32)>0),K32/L32,"") -> 5.1559994
A33: 32 | B33: ITRI | C33: Itron, Inc. | D33: Information Technology | E33: Scientific & Technical Instruments | F33: 0.005401 | G33: =SUM($F$2:F33) -> 0.794683 | H33: 91.32 | I33: 15.6103 | J33: 5.85 | K33: 3.9986 | L33: 1.7361 | M33: =IF(AND(N(K33)>0,N(L33)>0),K33/L33,"") -> 2.3032083
A34: 33 | B34: XE | C34: X-Energy, Inc. | D34: Industrials | E34: Specialty Industrial Machinery | F34: 0.005401 | G34: =SUM($F$2:F34) -> 0.800084 | H34: 16.38 | J34: -0.7 | K34: 6.6563 | L34: 44.294 | M34: =IF(AND(N(K34)>0,N(L34)>0),K34/L34,"") -> 0.15027543 | N34: Negative trailing EPS; P/E blank
A35: 34 | B35: EQIX | C35: Equinix, Inc. | D35: Real Estate | E35: REIT - Specialty | F35: 0.005301 | G35: =SUM($F$2:F35) -> 0.805385 | H35: 1037.66 | I35: 66.6448 | J35: 15.57 | K35: 102.3877 | L35: 10.338 | M35: =IF(AND(N(K35)>0,N(L35)>0),K35/L35,"") -> 9.9040143
A36: 35 | B36: SMR | C36: NuScale Power Corporation | D36: Industrials | E36: Specialty Industrial Machinery | F36: 0.005301 | G36: =SUM($F$2:F36) -> 0.810686 | H36: 8.68 | J36: -2.15 | K36: 3.5622 | L36: 333.2256 | M36: =IF(AND(N(K36)>0,N(L36)>0),K36/L36,"") -> 0.010690055 | N36: Negative trailing EPS; P/E blank
A37: 36 | B37: ATKR | C37: Atkore Inc. | D37: Industrials | E37: Electrical Equipment & Parts | F37: 0.005001 | G37: =SUM($F$2:F37) -> 0.815687 | H37: 94.51 | J37: -4.83 | K37: 3.1919 | L37: 1.088 | M37: =IF(AND(N(K37)>0,N(L37)>0),K37/L37,"") -> 2.9337316 | N37: Negative trailing EPS; P/E blank
A38: 37 | B38: UEC | C38: Uranium Energy Corp. | D38: Energy | E38: Uranium | F38: 0.005001 | G38: =SUM($F$2:F38) -> 0.820688 | H38: 9.95 | J38: -0.22 | K38: 4.924 | L38: 243.7614 | M38: =IF(AND(N(K38)>0,N(L38)>0),K38/L38,"") -> 0.020200081 | N38: Negative trailing EPS; P/E blank
A39: 38 | B39: ALAB | C39: Astera Labs, Inc. | D39: Information Technology | E39: Semiconductors | F39: 0.0048 | G39: =SUM($F$2:F39) -> 0.825488 | H39: 360.46 | I39: 178.4455 | J39: 2.02 | K39: 62.5344 | L39: 52.0288 | M39: =IF(AND(N(K39)>0,N(L39)>0),K39/L39,"") -> 1.2019189
A40: 39 | B40: NBIS | C40: Nebius Group N.V. | D40: Communication Services | E40: Internet Content & Information | F40: 0.0047 | G40: =SUM($F$2:F40) -> 0.830188 | H40: 226.61 | J40: -0.07 | K40: 61.6051 | L40: 45.4617 | M40: =IF(AND(N(K40)>0,N(L40)>0),K40/L40,"") -> 1.3550989 | N40: Negative trailing EPS; P/E blank
A41: 40 | B41: DNN | C41: Denison Mines Corp. | D41: Energy | E41: Uranium | F41: 0.0044 | G41: =SUM($F$2:F41) -> 0.834588 | H41: 2.82 | K41: 2.5528 | M41: =IF(AND(N(K41)>0,N(L41)>0),K41/L41,"") | N41: ADR: Yahoo mixes USD price with CAD earnings; P/E, EPS, P/S blanked
A42: 41 | B42: UUUU | C42: Energy Fuels Inc. | D42: Energy | E42: Uranium | F42: 0.0044 | G42: =SUM($F$2:F42) -> 0.838988 | H42: 11.6 | J42: -0.33 | K42: 3.0714 | L42: 29.0415 | M42: =IF(AND(N(K42)>0,N(L42)>0),K42/L42,"") -> 0.105759 | N42: Negative trailing EPS; P/E blank
...

Sheet Sectors
A1: GICS Sector | B1: Approx. Weight | C1: # of Tickers | D1: Avg P/E (simple, P/E<=100)
A2: Communication Services | B2: =SUMIF(Holdings!$D$2:$D$89,A2,Holdings!$F$2:$F$89) -> 0.046704 | C2: =COUNTIF(Holdings!$D$2:$D$89,A2) -> 2 | D2: =IFERROR(AVERAGEIFS(Holdings!$I$2:$I$89,Holdings!$D$2:$D$89,A2,Holdings!$I$2:$I$89,"<=100"),"") -> 16.9338
A3: Consumer Discretionary | B3: =SUMIF(Holdings!$D$2:$D$89,A3,Holdings!$F$2:$F$89) -> 0 | C3: =COUNTIF(Holdings!$D$2:$D$89,A3) -> 0 | D3: =IFERROR(AVERAGEIFS(Holdings!$I$2:$I$89,Holdings!$D$2:$D$89,A3,Holdings!$I$2:$I$89,"<=100"),"")
A4: Consumer Staples | B4: =SUMIF(Holdings!$D$2:$D$89,A4,Holdings!$F$2:$F$89) -> 0 | C4: =COUNTIF(Holdings!$D$2:$D$89,A4) -> 0 | D4: =IFERROR(AVERAGEIFS(Holdings!$I$2:$I$89,Holdings!$D$2:$D$89,A4,Holdings!$I$2:$I$89,"<=100"),"")
A5: Energy | B5: =SUMIF(Holdings!$D$2:$D$89,A5,Holdings!$F$2:$F$89) -> 0.067606 | C5: =COUNTIF(Holdings!$D$2:$D$89,A5) -> 8 | D5: =IFERROR(AVERAGEIFS(Holdings!$I$2:$I$89,Holdings!$D$2:$D$89,A5,Holdings!$I$2:$I$89,"<=100"),"") -> 80.0582
A6: Financials | B6: =SUMIF(Holdings!$D$2:$D$89,A6,Holdings!$F$2:$F$89) -> 0.0318 | C6: =COUNTIF(Holdings!$D$2:$D$89,A6) -> 9 | D6: =IFERROR(AVERAGEIFS(Holdings!$I$2:$I$89,Holdings!$D$2:$D$89,A6,Holdings!$I$2:$I$89,"<=100"),"") -> 10.0566
A7: Health Care | B7: =SUMIF(Holdings!$D$2:$D$89,A7,Holdings!$F$2:$F$89) -> 0 | C7: =COUNTIF(Holdings!$D$2:$D$89,A7) -> 0 | D7: =IFERROR(AVERAGEIFS(Holdings!$I$2:$I$89,Holdings!$D$2:$D$89,A7,Holdings!$I$2:$I$89,"<=100"),"")
A8: Industrials | B8: =SUMIF(Holdings!$D$2:$D$89,A8,Holdings!$F$2:$F$89) -> 0.527051 | C8: =COUNTIF(Holdings!$D$2:$D$89,A8) -> 28 | D8: =IFERROR(AVERAGEIFS(Holdings!$I$2:$I$89,Holdings!$D$2:$D$89,A8,Holdings!$I$2:$I$89,"<=100"),"") -> 34.524417
A9: Information Technology | B9: =SUMIF(Holdings!$D$2:$D$89,A9,Holdings!$F$2:$F$89) -> 0.181114 | C9: =COUNTIF(Holdings!$D$2:$D$89,A9) -> 21 | D9: =IFERROR(AVERAGEIFS(Holdings!$I$2:$I$89,Holdings!$D$2:$D$89,A9,Holdings!$I$2:$I$89,"<=100"),"") -> 43.9318
A10: Materials | B10: =SUMIF(Holdings!$D$2:$D$89,A10,Holdings!$F$2:$F$89) -> 0 | C10: =COUNTIF(Holdings!$D$2:$D$89,A10) -> 0 | D10: =IFERROR(AVERAGEIFS(Holdings!$I$2:$I$89,Holdings!$D$2:$D$89,A10,Holdings!$I$2:$I$89,"<=100"),"")
A11: Real Estate | B11: =SUMIF(Holdings!$D$2:$D$89,A11,Holdings!$F$2:$F$89) -> 0.009401 | C11: =COUNTIF(Holdings!$D$2:$D$89,A11) -> 2 | D11: =IFERROR(AVERAGEIFS(Holdings!$I$2:$I$89,Holdings!$D$2:$D$89,A11,Holdings!$I$2:$I$89,"<=100"),"") -> 77.79545
A12: Utilities | B12: =SUMIF(Holdings!$D$2:$D$89,A12,Holdings!$F$2:$F$89) -> 0.134112 | C12: =COUNTIF(Holdings!$D$2:$D$89,A12) -> 17 | D12: =IFERROR(AVERAGEIFS(Holdings!$I$2:$I$89,Holdings!$D$2:$D$89,A12,Holdings!$I$2:$I$89,"<=100"),"") -> 21.301708
A13: Unclassified (no sector retrieved) | B13: =1-SUM(B2:B12) -> 0.002212 | C13: =COUNTBLANK(Holdings!$D$2:$D$89) -> 1
A14: Total | B14: =SUM(B2:B13) -> 1 | C14: =SUM(C2:C13) -> 88

Sheet Overlap vs S&P 500
A1: Holdings shared with the S&P 500 (S&P weights from the companion S&P 500 workbook, Sept 2026)
A2: 23 of 88 holdings are S&P 500 members
A3: Share of this fund's weight that is inside the S&P 500 | B3: 0.6663
A4: Share of the S&P 500 that those names represent | B4: 0.1671
A6: Ticker | B6: Weight in this fund | C6: Weight in S&P 500 | D6: Ratio (fund ÷ S&P)
A7: ETN | B7: 0.0844 | C7: 0.0024 | D7: =IF(C7>0,B7/C7,"") -> 35.166667
A8: PWR | B8: 0.0812 | C8: 0.0014 | D8: =IF(C8>0,B8/C8,"") -> 58
A9: GEV | B9: 0.0791 | C9: 0.0036 | D9: =IF(C9>0,B9/C9,"") -> 21.972222
A10: VRT | B10: 0.065 | C10: 0.0014 | D10: =IF(C10>0,B10/C10,"") -> 46.428571
A11: BE | B11: 0.0517 | C11: 0 | D11: =IF(C11>0,B11/C11,"")
A12: GOOGL | B12: 0.042 | C12: 0.0316 | D12: =IF(C12>0,B12/C12,"") -> 1.3291139
A13: NVDA | B13: 0.0405 | C13: 0.0773 | D13: =IF(C13>0,B13/C13,"") -> 0.52393273
A14: AVGO | B14: 0.0395 | C14: 0.0247 | D14: =IF(C14>0,B14/C14,"") -> 1.5991903
A15: CEG | B15: 0.0305 | C15: 0.0013 | D15: =IF(C15>0,B15/C15,"") -> 23.461538
A16: AMD | B16: 0.0275 | C16: 0.0134 | D16: =IF(C16>0,B16/C16,"") -> 2.0522388
A17: HUBB | B17: 0.0183 | C17: 0.0003 | D17: =IF(C17>0,B17/C17,"") -> 61
A18: VST | B18: 0.0158 | C18: 0.0007 | D18: =IF(C18>0,B18/C18,"") -> 22.571429
... A29: PNW | B29: 0.0027 | C29: 0.0002 | D29: =IF(C29>0,B29/C29,"") -> 13.5
A30: Total (shared names) | B30: =SUM(B7:B29) -> 0.6662 | C30: =SUM(C7:C29) -> 0.1671

Sheet Notes
A1: AIPO: Defiance AI & Power Infrastructure ETF, constituents, weights, trailing P/E and fund history
A2: Holdings and weights: Defiance's full-holdings page (defianceetfs.com/aipo-full-holdings). Cash lines are removed and weights rescaled to 100%. About 90 companies in power equipment, utilities, grid contractors, data-center hardware and the AI chip names that drive the demand. As of Sep 22, 2026.
A3: P/E (TTM), EPS (TTM), Market Cap, Price/Sales, Price, Company name, GICS sector and Sub-Industry: Yahoo Finance via the yfinance library, retrieved Sept 23, 2026. Yahoo's sectors are mapped to GICS sector names; Yahoo's industry label stands in for the GICS sub-industry.
A4: Revenue TTM ($B) is derived as Market Cap / Price-to-Sales, so it is approximate. Blank where either input is missing.
A5: The fund is 14 months old: there is no full calendar year of returns yet, so the Annual Returns and By Decade tabs carry only the note. Two-thirds of the weight is S&P 500 members (Eaton, Quanta, GE Vernova, Vertiv, Constellation, Nvidia, Broadcom). The Sectors tab average excludes blanks and P/Es above 100.
A6: Cumulative Weight assumes the default sort by rank; after re-sorting it shows the running weight in the new order.
A7: Overlap tab: every holding whose ticker also appears in the companion S&P 500 workbook, with its weight in each. 'Ratio' shows how many times more concentrated the name is here than in the index.
A8: For information only; not investment advice.
A10: Historical tabs 'Annual Returns' (None-2025) and 'By Decade': the fund launched July 25, 2025, so returns are the fund's own, from Yahoo Finance daily prices. Price Return uses closing prices on the last trading day of each year; Total Return uses dividend-adjusted closes (distributions reinvested). S&P 500 total return (SPY, dividend-adjusted) is shown alongside for the same years. The launch year is a stub and is excluded; 2026 is incomplete and excluded.
A11: Real returns use December-over-December US CPI-U (NSA) from the BLS (series CUUR0000SA0).
A12: Fees: the fund's expense ratio is 0.85% (check prospectus); returns above are net of it. The index funds in the companion workbooks charge 0.03% to 0.05%.

Sheet Annual Returns
A1: Year | B1: Decade | C1: Price Return | D1: Total Return (w/ dividends) | E1: Real Price Return (inflation-adj.) | F1: Real Total Return (inflation-adj.) | G1: Up / Down (Total Return) | H1: Growth of $1 (Total Return) | I1: Growth of $1 (Price only) | J1: S&P 500 Total Return (SPY, comparison)
A2: No complete calendar year of returns yet (fund launched July 25, 2025). See the Notes tab.

Sheet By Decade
A1: No complete calendar year of returns yet (fund launched July 25, 2025). See the Notes tab.
