Workbook

Sheet Holdings
A1: Rank | B1: Ticker | C1: Company | D1: GICS Sector | E1: Sub-Industry | F1: Weight | G1: Cumulative Weight | H1: Price ($) | I1: P/E (TTM) | J1: EPS (TTM) | K1: Mkt Cap ($B) | L1: Price/Sales | M1: Revenue TTM ($B) | N1: Notes
A2: 1 | B2: ISRG | C2: Intuitive Surgical, Inc. | D2: Health Care | E2: Medical Instruments & Supplies | F2: 0.084381 | G2: =SUM($F$2:F2) -> 0.084381 | H2: 398.3 | I2: 45.6243 | J2: 8.73 | K2: 142.7021 | L2: 12.9325 | M2: =IF(AND(N(K2)>0,N(L2)>0),K2/L2,"") -> 11.034379
A3: 2 | B3: ABBN | C3: ABB Ltd | D3: Industrials | E3: Electrical Equipment & Parts | F3: 0.082973 | G3: =SUM($F$2:F3) -> 0.167354 | I3: 36.7946 | J3: 2.24 | L3: 4.1744 | M3: =IF(AND(N(K3)>0,N(L3)>0),K3/L3,"") | N3: Local-currency listing (CHF); price and market cap blank
A4: 3 | B4: 6954 | C4: Fanuc Corporation | D4: Industrials | E4: Specialty Industrial Machinery | F4: 0.080559 | G4: =SUM($F$2:F4) -> 0.247913 | I4: 33.6938 | J4: 178.49 | L4: 6.2613 | M4: =IF(AND(N(K4)>0,N(L4)>0),K4/L4,"") | N4: Local-currency listing (JPY); price and market cap blank
A5: 4 | B5: NVDA | C5: NVIDIA Corporation | D5: Information Technology | E5: Semiconductors | F5: 0.079654 | G5: =SUM($F$2:F5) -> 0.327567 | H5: 225.51 | I5: 28.4735 | J5: 7.92 | K5: 5445.3899 | L5: 17.9734 | M5: =IF(AND(N(K5)>0,N(L5)>0),K5/L5,"") -> 302.96938
A6: 5 | B6: 6861 | C6: Keyence Corporation | D6: Information Technology | E6: Scientific & Technical Instruments | F6: 0.077643 | G6: =SUM($F$2:F6) -> 0.40521 | I6: 42.0421 | J6: 1837.92 | L6: 14.9342 | M6: =IF(AND(N(K6)>0,N(L6)>0),K6/L6,"") | N6: Local-currency listing (JPY); price and market cap blank
A7: 6 | B7: 6273 | C7: SMC Corporation | D7: Industrials | E7: Specialty Industrial Machinery | F7: 0.044453 | G7: =SUM($F$2:F7) -> 0.449663 | I7: 25.7545 | J7: 2639.93 | L7: 4.6509 | M7: =IF(AND(N(K7)>0,N(L7)>0),K7/L7,"") | N7: Local-currency listing (JPY); price and market cap blank
A8: 7 | B8: 6383 | C8: Daifuku Co., Ltd. | D8: Industrials | E8: Specialty Industrial Machinery | F8: 0.032887 | G8: =SUM($F$2:F8) -> 0.48255 | I8: 25.5268 | J8: 216.87 | L8: 2.9844 | M8: =IF(AND(N(K8)>0,N(L8)>0),K8/L8,"") | N8: Local-currency listing (JPY); price and market cap blank
A9: 8 | B9: AUR | C9: Aurora Innovation, Inc. | D9: Consumer Discretionary | E9: Auto Parts | F9: 0.027758 | G9: =SUM($F$2:F9) -> 0.510308 | H9: 6.32 | J9: -0.46 | K9: 12.6663 | L9: 2533.2522 | M9: =IF(AND(N(K9)>0,N(L9)>0),K9/L9,"") -> 0.0050000154 | N9: Negative trailing EPS; P/E blank
A10: 9 | B10: 300124 | C10: Shenzhen Inovance Technology Co.,Ltd | D10: Industrials | E10: Electrical Equipment & Parts | F10: 0.025948 | G10: =SUM($F$2:F10) -> 0.536256 | I10: 29.618 | J10: 1.78 | L10: 2.8995 | M10: =IF(AND(N(K10)>0,N(L10)>0),K10/L10,"") | N10: Local-currency listing (CNY); price and market cap blank
A11: 10 | B11: CGNX | C11: Cognex Corporation | D11: Information Technology | E11: Scientific & Technical Instruments | F11: 0.024942 | G11: =SUM($F$2:F11) -> 0.561198 | H11: 58.19 | I11: 55.9519 | J11: 1.04 | K11: 9.7889 | L11: 8.9895 | M11: =IF(AND(N(K11)>0,N(L11)>0),K11/L11,"") -> 1.088926
A12: 11 | B12: TSLA | C12: Tesla, Inc. | D12: Consumer Discretionary | E12: Auto Manufacturers | F12: 0.020718 | G12: =SUM($F$2:F12) -> 0.581916 | H12: 380.12 | I12: 345.5636 | J12: 1.1 | K12: 1501.302 | L12: 14.4887 | M12: =IF(AND(N(K12)>0,N(L12)>0),K12/L12,"") -> 103.61882
A13: 12 | B13: GOOGL | C13: Alphabet Inc. | D13: Communication Services | E13: Internet Content & Information | F13: 0.020316 | G13: =SUM($F$2:F13) -> 0.602232 | H13: 337.83 | I13: 16.9338 | J13: 19.95 | K13: 4131.6387 | L13: 9.2665 | M13: =IF(AND(N(K13)>0,N(L13)>0),K13/L13,"") -> 445.86831
A14: 13 | B14: 300757 | C14: RoboTechnik Intelligent Technology Co., Ltd. | D14: Industrials | E14: Specialty Industrial Machinery | F14: 0.020316 | G14: =SUM($F$2:F14) -> 0.622548 | J14: -0.18 | L14: 76.5233 | M14: =IF(AND(N(K14)>0,N(L14)>0),K14/L14,"") | N14: Local-currency listing (CNY); price and market cap blank; Negative trailing EPS; P/E blank
A15: 14 | B15: 6645 | C15: OMRON Corporation | D15: Information Technology | E15: Electronic Components | F15: 0.020215 | G15: =SUM($F$2:F15) -> 0.642763 | I15: 36.3401 | J15: 173.94 | L15: 1.533 | M15: =IF(AND(N(K15)>0,N(L15)>0),K15/L15,"") | N15: Local-currency listing (JPY); price and market cap blank
A16: 15 | B16: DE | C16: Deere & Company | D16: Industrials | E16: Farm & Heavy Construction Machinery | F16: 0.019612 | G16: =SUM($F$2:F16) -> 0.662375 | H16: 709.48 | I16: 39.4156 | J16: 18 | K16: 191.2938 | L16: 3.9914 | M16: =IF(AND(N(K16)>0,N(L16)>0),K16/L16,"") -> 47.926492
A17: 16 | B17: 6506 | C17: YASKAWA Electric Corporation | D17: Industrials | E17: Electrical Equipment & Parts | F17: 0.018606 | G17: =SUM($F$2:F17) -> 0.680981 | I17: 32.9653 | J17: 135.87 | L17: 2.0914 | M17: =IF(AND(N(K17)>0,N(L17)>0),K17/L17,"") | N17: Local-currency listing (JPY); price and market cap blank
A18: 17 | B18: 9660 | C18: Horizon Robotics | D18: Information Technology | E18: Software - Application | F18: 0.018103 | G18: =SUM($F$2:F18) -> 0.699084 | J18: -0.73 | L18: 14.8982 | M18: =IF(AND(N(K18)>0,N(L18)>0),K18/L18,"") | N18: Local-currency listing (HKD); price and market cap blank; Negative trailing EPS; P/E blank
A19: 18 | B19: 1810 | C19: Xiaomi Corporation | D19: Information Technology | E19: Consumer Electronics | F19: 0.016192 | G19: =SUM($F$2:F19) -> 0.715276 | I19: 18.2517 | J19: 1.43 | L19: 1.5324 | M19: =IF(AND(N(K19)>0,N(L19)>0),K19/L19,"") | N19: Local-currency listing (HKD); price and market cap blank
A20: 19 | B20: 277810 | C20: Rainbow Robotics | F20: 0.01579 | G20: =SUM($F$2:F20) -> 0.731066 | M20: =IF(AND(N(K20)>0,N(L20)>0),K20/L20,"") | N20: Local-currency listing (KRW); price and market cap blank
A21: 20 | B21: SYM | C21: Symbotic Inc. | D21: Industrials | E21: Specialty Industrial Machinery | F21: 0.014684 | G21: =SUM($F$2:F21) -> 0.74575 | H21: 43.69 | I21: 1092.25 | J21: 0.04 | K21: 26.4484 | L21: 9.9965 | M21: =IF(AND(N(K21)>0,N(L21)>0),K21/L21,"") -> 2.645766 | N21: P/E reflects near-zero earnings
A22: 21 | B22: AUTO | C22: AutoStore Holdings Ltd. | D22: Industrials | E22: Specialty Industrial Machinery | F22: 0.014583 | G22: =SUM($F$2:F22) -> 0.760333 | I22: 35.3778 | J22: 0.45 | L22: 78.9726 | M22: =IF(AND(N(K22)>0,N(L22)>0),K22/L22,"") | N22: Local-currency listing (NOK); price and market cap blank
A23: 22 | B23: 9880 | C23: Ubtech Robotics Corp Ltd | D23: Industrials | E23: Specialty Industrial Machinery | F23: 0.011264 | G23: =SUM($F$2:F23) -> 0.771597 | J23: -1.44 | L23: 15.0241 | M23: =IF(AND(N(K23)>0,N(L23)>0),K23/L23,"") | N23: Local-currency listing (HKD); price and market cap blank; Negative trailing EPS; P/E blank
A24: 23 | B24: 6134 | C24: Fuji Corporation | D24: Industrials | E24: Specialty Industrial Machinery | F24: 0.011264 | G24: =SUM($F$2:F24) -> 0.782861 | I24: 41.2788 | J24: 178.76 | L24: 3.2481 | M24: =IF(AND(N(K24)>0,N(L24)>0),K24/L24,"") | N24: Local-currency listing (JPY); price and market cap blank
A25: 24 | B25: 688017 | C25: Leader Harmonious Drive Systems Co., Ltd. | D25: Industrials | E25: Specialty Industrial Machinery | F25: 0.01056 | G25: =SUM($F$2:F25) -> 0.793421 | I25: 372.5974 | J25: 0.77 | L25: 78.7562 | M25: =IF(AND(N(K25)>0,N(L25)>0),K25/L25,"") | N25: Local-currency listing (CNY); price and market cap blank
A26: 25 | B26: ROK | C26: Rockwell Automation, Inc. | D26: Industrials | E26: Specialty Industrial Machinery | F26: 0.010359 | G26: =SUM($F$2:F26) -> 0.80378 | H26: 432.89 | I26: 40.5328 | J26: 10.68 | K26: 48.1694 | L26: 5.3683 | M26: =IF(AND(N(K26)>0,N(L26)>0),K26/L26,"") -> 8.9729337
A27: 26 | B27: 6324 | C27: Harmonic Drive Systems Inc. | D27: Industrials | E27: Specialty Industrial Machinery | F27: 0.009554 | G27: =SUM($F$2:F27) -> 0.813334 | I27: 375.7467 | J27: 16.74 | L27: 9.4905 | M27: =IF(AND(N(K27)>0,N(L27)>0),K27/L27,"") | N27: Local-currency listing (JPY); price and market cap blank
A28: 27 | B28: 2049 | C28: Hiwin Technologies Corporation | D28: Industrials | E28: Tools & Accessories | F28: 0.009253 | G28: =SUM($F$2:F28) -> 0.822587 | I28: 49.0152 | J28: 6.6 | L28: 4.3376 | M28: =IF(AND(N(K28)>0,N(L28)>0),K28/L28,"") | N28: Local-currency listing (TWD); price and market cap blank
A29: 28 | B29: 454910 | C29: Doosan Robotics Inc. | D29: Industrials | E29: Specialty Industrial Machinery | F29: 0.008549 | G29: =SUM($F$2:F29) -> 0.831136 | L29: 81.7533 | M29: =IF(AND(N(K29)>0,N(L29)>0),K29/L29,"") | N29: Local-currency listing (KRW); price and market cap blank
A30: 29 | B30: TECN | C30: Tecan Group AG | D30: Health Care | E30: Medical Instruments & Supplies | F30: 0.008549 | G30: =SUM($F$2:F30) -> 0.839685 | J30: -9.16 | L30: 3.0828 | M30: =IF(AND(N(K30)>0,N(L30)>0),K30/L30,"") | N30: Local-currency listing (CHF); price and market cap blank; Negative trailing EPS; P/E blank
A31: 30 | B31: 108490 | C31: Robotis Co Ltd | F31: 0.008146 | G31: =SUM($F$2:F31) -> 0.847831 | M31: =IF(AND(N(K31)>0,N(L31)>0),K31/L31,"") | N31: Local-currency listing (KRW); price and market cap blank
A32: 31 | B32: OUST | C32: Ouster, Inc. | D32: Information Technology | E32: Electronic Components | F32: 0.007342 | G32: =SUM($F$2:F32) -> 0.855173 | H32: 39.38 | J32: -0.83 | K32: 2.8398 | L32: 13.8589 | M32: =IF(AND(N(K32)>0,N(L32)>0),K32/L32,"") -> 0.20490804 | N32: Negative trailing EPS; P/E blank
A33: 32 | B33: PONY | C33: Pony AI Inc. | D33: Information Technology | E33: Information Technology Services | F33: 0.006437 | G33: =SUM($F$2:F33) -> 0.86161 | H33: 7.26 | J33: -0.33 | K33: 3.1538 | L33: 25.2233 | M33: =IF(AND(N(K33)>0,N(L33)>0),K33/L33,"") -> 0.12503519 | N33: Negative trailing EPS; P/E blank
A34: 33 | B34: 2252 | C34: Shanghai MicroPort MedBot (Group) Co., Ltd. | D34: Health Care | E34: Medical Devices | F34: 0.006336 | G34: =SUM($F$2:F34) -> 0.867946 | J34: -0.28 | L34: 39.6386 | M34: =IF(AND(N(K34)>0,N(L34)>0),K34/L34,"") | N34: Local-currency listing (HKD); price and market cap blank; Negative trailing EPS; P/E blank
A35: 34 | B35: EXA | C35: Exail Technologies | D35: Industrials | E35: Aerospace & Defense | F35: 0.006034 | G35: =SUM($F$2:F35) -> 0.87398 | I35: 735.2941 | J35: 0.17 | L35: 4.219 | M35: =IF(AND(N(K35)>0,N(L35)>0),K35/L35,"") | N35: Local-currency listing (EUR); price and market cap blank; P/E reflects near-zero earnings
A36: 35 | B36: 688169 | C36: Beijing Roborock Technology Co., Ltd. | D36: Industrials | E36: Specialty Industrial Machinery | F36: 0.006034 | G36: =SUM($F$2:F36) -> 0.880014 | I36: 17.9322 | J36: 6.49 | L36: 1.447 | M36: =IF(AND(N(K36)>0,N(L36)>0),K36/L36,"") | N36: Local-currency listing (CNY); price and market cap blank
A37: 36 | B37: 603486 | C37: Ecovacs Robotics Co., Ltd. | D37: Consumer Discretionary | E37: Furnishings, Fixtures & Appliances | F37: 0.005833 | G37: =SUM($F$2:F37) -> 0.885847 | I37: 14.5 | J37: 3.5 | L37: 1.4202 | M37: =IF(AND(N(K37)>0,N(L37)>0),K37/L37,"") | N37: Local-currency listing (CNY); price and market cap blank
A38: 37 | B38: 688297 | C38: AVIC (Chengdu)UAS Co., Ltd. | D38: Industrials | E38: Aerospace & Defense | F38: 0.005833 | G38: =SUM($F$2:F38) -> 0.89168 | I38: 268.9375 | J38: 0.16 | L38: 6.8972 | M38: =IF(AND(N(K38)>0,N(L38)>0),K38/L38,"") | N38: Local-currency listing (CNY); price and market cap blank
A39: 38 | B39: HSAI | C39: Hesai Group | D39: Consumer Discretionary | E39: Auto Parts | F39: 0.005632 | G39: =SUM($F$2:F39) -> 0.897312 | H39: 16.31 | K39: 20.5039 | M39: =IF(AND(N(K39)>0,N(L39)>0),K39/L39,"") | N39: ADR: Yahoo mixes USD price with CNY earnings; P/E, EPS, P/S blanked
A40: 39 | B40: BIDU | C40: Baidu, Inc. | D40: Communication Services | E40: Internet Content & Information | F40: 0.005532 | G40: =SUM($F$2:F40) -> 0.902844 | H40: 89.78 | K40: 30.5961 | M40: =IF(AND(N(K40)>0,N(L40)>0),K40/L40,"") | N40: ADR: Yahoo mixes USD price with CNY earnings; P/E, EPS, P/S blanked
...

Sheet Sectors
A1: GICS Sector | B1: Approx. Weight | C1: # of Tickers | D1: Avg P/E (simple, P/E<=100)
A2: Communication Services | B2: =SUMIF(Holdings!$D$2:$D$81,A2,Holdings!$F$2:$F$81) -> 0.025848 | C2: =COUNTIF(Holdings!$D$2:$D$81,A2) -> 2 | D2: =IFERROR(AVERAGEIFS(Holdings!$I$2:$I$81,Holdings!$D$2:$D$81,A2,Holdings!$I$2:$I$81,"<=100"),"") -> 16.9338
A3: Consumer Discretionary | B3: =SUMIF(Holdings!$D$2:$D$81,A3,Holdings!$F$2:$F$81) -> 0.061751 | C3: =COUNTIF(Holdings!$D$2:$D$81,A3) -> 5 | D3: =IFERROR(AVERAGEIFS(Holdings!$I$2:$I$81,Holdings!$D$2:$D$81,A3,Holdings!$I$2:$I$81,"<=100"),"") -> 14.5
A4: Consumer Staples | B4: =SUMIF(Holdings!$D$2:$D$81,A4,Holdings!$F$2:$F$81) -> 0 | C4: =COUNTIF(Holdings!$D$2:$D$81,A4) -> 0 | D4: =IFERROR(AVERAGEIFS(Holdings!$I$2:$I$81,Holdings!$D$2:$D$81,A4,Holdings!$I$2:$I$81,"<=100"),"")
A5: Energy | B5: =SUMIF(Holdings!$D$2:$D$81,A5,Holdings!$F$2:$F$81) -> 0 | C5: =COUNTIF(Holdings!$D$2:$D$81,A5) -> 0 | D5: =IFERROR(AVERAGEIFS(Holdings!$I$2:$I$81,Holdings!$D$2:$D$81,A5,Holdings!$I$2:$I$81,"<=100"),"")
A6: Financials | B6: =SUMIF(Holdings!$D$2:$D$81,A6,Holdings!$F$2:$F$81) -> 0 | C6: =COUNTIF(Holdings!$D$2:$D$81,A6) -> 0 | D6: =IFERROR(AVERAGEIFS(Holdings!$I$2:$I$81,Holdings!$D$2:$D$81,A6,Holdings!$I$2:$I$81,"<=100"),"")
A7: Health Care | B7: =SUMIF(Holdings!$D$2:$D$81,A7,Holdings!$F$2:$F$81) -> 0.111637 | C7: =COUNTIF(Holdings!$D$2:$D$81,A7) -> 8 | D7: =IFERROR(AVERAGEIFS(Holdings!$I$2:$I$81,Holdings!$D$2:$D$81,A7,Holdings!$I$2:$I$81,"<=100"),"") -> 42.44905
A8: Industrials | B8: =SUMIF(Holdings!$D$2:$D$81,A8,Holdings!$F$2:$F$81) -> 0.490193 | C8: =COUNTIF(Holdings!$D$2:$D$81,A8) -> 40 | D8: =IFERROR(AVERAGEIFS(Holdings!$I$2:$I$81,Holdings!$D$2:$D$81,A8,Holdings!$I$2:$I$81,"<=100"),"") -> 31.725612
A9: Information Technology | B9: =SUMIF(Holdings!$D$2:$D$81,A9,Holdings!$F$2:$F$81) -> 0.278285 | C9: =COUNTIF(Holdings!$D$2:$D$81,A9) -> 18 | D9: =IFERROR(AVERAGEIFS(Holdings!$I$2:$I$81,Holdings!$D$2:$D$81,A9,Holdings!$I$2:$I$81,"<=100"),"") -> 52.729487
A10: Materials | B10: =SUMIF(Holdings!$D$2:$D$81,A10,Holdings!$F$2:$F$81) -> 0 | C10: =COUNTIF(Holdings!$D$2:$D$81,A10) -> 0 | D10: =IFERROR(AVERAGEIFS(Holdings!$I$2:$I$81,Holdings!$D$2:$D$81,A10,Holdings!$I$2:$I$81,"<=100"),"")
A11: Real Estate | B11: =SUMIF(Holdings!$D$2:$D$81,A11,Holdings!$F$2:$F$81) -> 0 | C11: =COUNTIF(Holdings!$D$2:$D$81,A11) -> 0 | D11: =IFERROR(AVERAGEIFS(Holdings!$I$2:$I$81,Holdings!$D$2:$D$81,A11,Holdings!$I$2:$I$81,"<=100"),"")
A12: Utilities | B12: =SUMIF(Holdings!$D$2:$D$81,A12,Holdings!$F$2:$F$81) -> 0 | C12: =COUNTIF(Holdings!$D$2:$D$81,A12) -> 0 | D12: =IFERROR(AVERAGEIFS(Holdings!$I$2:$I$81,Holdings!$D$2:$D$81,A12,Holdings!$I$2:$I$81,"<=100"),"")
A13: Unclassified (no sector retrieved) | B13: =1-SUM(B2:B12) -> 0.032286 | C13: =COUNTBLANK(Holdings!$D$2:$D$81) -> 7
A14: Total | B14: =SUM(B2:B13) -> 1 | C14: =SUM(C2:C13) -> 80

Sheet Overlap vs S&P 500
A1: Holdings shared with the S&P 500 (S&P weights from the companion S&P 500 workbook, Sept 2026)
A2: 6 of 80 holdings are S&P 500 members
A3: Share of this fund's weight that is inside the S&P 500 | B3: 0.235
A4: Share of the S&P 500 that those names represent | B4: 0.135
A6: Ticker | B6: Weight in this fund | C6: Weight in S&P 500 | D6: Ratio (fund ÷ S&P)
A7: ISRG | B7: 0.0844 | C7: 0.002 | D7: =IF(C7>0,B7/C7,"") -> 42.2
A8: NVDA | B8: 0.0797 | C8: 0.0773 | D8: =IF(C8>0,B8/C8,"") -> 1.0310479
A9: TSLA | B9: 0.0207 | C9: 0.0208 | D9: =IF(C9>0,B9/C9,"") -> 0.99519231
A10: GOOGL | B10: 0.0203 | C10: 0.0316 | D10: =IF(C10>0,B10/C10,"") -> 0.64240506
A11: DE | B11: 0.0196 | C11: 0.0026 | D11: =IF(C11>0,B11/C11,"") -> 7.5384615
A12: ROK | B12: 0.0104 | C12: 0.0007 | D12: =IF(C12>0,B12/C12,"") -> 14.857143
A13: Total (shared names) | B13: =SUM(B7:B12) -> 0.2351 | C13: =SUM(C7:C12) -> 0.135

Sheet Notes
A1: BOTZ: Global X Robotics & Artificial Intelligence ETF, constituents, weights, trailing P/E and fund history
A2: Holdings and weights: Global X's daily full-holdings file (assets.globalxetfs.com). Cash and currency lines are removed and weights rescaled to 100%. BOTZ tracks the Indxx Global Robotics & Artificial Intelligence Thematic Index: about 80 companies worldwide, roughly 40% Japanese, cap-weighted with caps. Local tickers (e.g. 6954 = Fanuc, 6861 = Keyence) are Global X's; the Yahoo symbol is in the Notes column where fundamentals were found. As of Sep 22, 2026.
A3: P/E (TTM), EPS (TTM), Market Cap, Price/Sales, Price, Company name, GICS sector and Sub-Industry: Yahoo Finance via the yfinance library, retrieved Sept 23, 2026. Yahoo's sectors are mapped to GICS sector names; Yahoo's industry label stands in for the GICS sub-industry.
A4: Revenue TTM ($B) is derived as Market Cap / Price-to-Sales, so it is approximate. Blank where either input is missing.
A5: About half the fund is non-US industrial automation (Keyence, Fanuc, SMC, Daifuku, ABB) and the rest US names led by Intuitive Surgical and Nvidia. Local-currency prices and market caps are left blank rather than converted. The Sectors tab average excludes blanks and P/Es above 100.
A6: Cumulative Weight assumes the default sort by rank; after re-sorting it shows the running weight in the new order.
A7: Overlap tab: every holding whose ticker also appears in the companion S&P 500 workbook, with its weight in each. 'Ratio' shows how many times more concentrated the name is here than in the index.
A8: For information only; not investment advice.
A10: Historical tabs 'Annual Returns' (2017-2025) and 'By Decade': the fund launched September 13, 2016, so returns are the fund's own, from Yahoo Finance daily prices. Price Return uses closing prices on the last trading day of each year; Total Return uses dividend-adjusted closes (distributions reinvested). S&P 500 total return (SPY, dividend-adjusted) is shown alongside for the same years. The launch year is a stub and is excluded; 2026 is incomplete and excluded.
A11: Real returns use December-over-December US CPI-U (NSA) from the BLS (series CUUR0000SA0).
A12: Fees: the fund's expense ratio is 0.68%; returns above are net of it. The index funds in the companion workbooks charge 0.03% to 0.05%.

Sheet Annual Returns
A1: Year | B1: Decade | C1: Price Return | D1: Total Return (w/ dividends) | E1: Real Price Return (inflation-adj.) | F1: Real Total Return (inflation-adj.) | G1: Up / Down (Total Return) | H1: Growth of $1 (Total Return) | I1: Growth of $1 (Price only) | J1: S&P 500 Total Return (SPY, comparison)
A2: 2017 | B2: =INT(A2/10)*10&"s" -> 2010s | C2: 0.58 | D2: 0.5801 | E2: 0.5474 | F2: 0.5475 | G2: =IF(D2>=0,"Up","Down") -> Up | H2: =1+D2 -> 1.5801 | I2: =1+C2 -> 1.58 | J2: 0.2171
A3: 2018 | B3: =INT(A3/10)*10&"s" -> 2010s | C3: -0.2937 | D3: -0.2834 | E3: -0.3069 | F3: -0.2969 | G3: =IF(D3>=0,"Up","Down") -> Down | H3: =H2*(1+D3) -> 1.1322997 | I3: =I2*(1+C3) -> 1.115954 | J3: -0.0457
A4: 2019 | B4: =INT(A4/10)*10&"s" -> 2010s | C4: 0.3065 | D4: 0.318 | E4: 0.2773 | F4: 0.2886 | G4: =IF(D4>=0,"Up","Down") -> Up | H4: =H3*(1+D4) -> 1.492371 | I4: =I3*(1+C4) -> 1.4579939 | J4: 0.3122
A5: 2020 | B5: =INT(A5/10)*10&"s" -> 2020s | C5: 0.5151 | D5: 0.5192 | E5: 0.4947 | F5: 0.4988 | G5: =IF(D5>=0,"Up","Down") -> Up | H5: =H4*(1+D5) -> 2.26721 | I5: =I4*(1+C5) -> 2.2090066 | J5: 0.1833
A6: 2021 | B6: =INT(A6/10)*10&"s" -> 2020s | C6: 0.0847 | D6: 0.0865 | E6: 0.0134 | F6: 0.015 | G6: =IF(D6>=0,"Up","Down") -> Up | H6: =H5*(1+D6) -> 2.4633236 | I6: =I5*(1+C6) -> 2.3961094 | J6: 0.2873
A7: 2022 | B7: =INT(A7/10)*10&"s" -> 2020s | C7: -0.4282 | D7: -0.4269 | E7: -0.4629 | F7: -0.4617 | G7: =IF(D7>=0,"Up","Down") -> Down | H7: =H6*(1+D7) -> 1.4117308 | I7: =I6*(1+C7) -> 1.3700954 | J7: -0.1818
A8: 2023 | B8: =INT(A8/10)*10&"s" -> 2020s | C8: 0.3869 | D8: 0.3896 | E8: 0.3419 | F8: 0.3446 | G8: =IF(D8>=0,"Up","Down") -> Up | H8: =H7*(1+D8) -> 1.9617411 | I8: =I7*(1+C8) -> 1.9001853 | J8: 0.2618
A9: 2024 | B9: =INT(A9/10)*10&"s" -> 2020s | C9: 0.1211 | D9: 0.1226 | E9: 0.0896 | F9: 0.0911 | G9: =IF(D9>=0,"Up","Down") -> Up | H9: =H8*(1+D9) -> 2.2022505 | I9: =I8*(1+C9) -> 2.1302977 | J9: 0.2489
A10: 2025 | B10: =INT(A10/10)*10&"s" -> 2020s | C10: 0.134 | D10: 0.1416 | E10: 0.1044 | F10: 0.1119 | G10: =IF(D10>=0,"Up","Down") -> Up | H10: =H9*(1+D10) -> 2.5140892 | I10: =I9*(1+C10) -> 2.4157576 | J10: 0.1772
A12: Summary
A13: Years | C13: =COUNT(A2:A10) -> 9
A14: Up years | C14: =COUNTIF(D2:D10,">=0") -> 7
A15: Down years | C15: =COUNTIF(D2:D10,"<0") -> 2
A16: Average annual total return | C16: =AVERAGE(D2:D10) -> 0.16081111
A17: Annualized (CAGR) total return | C17: =(H10)^(1/COUNT(A2:A10))-1 -> 0.10786475
A18: Average annual real total return | C18: =AVERAGE(F2:F10) -> 0.12654444
A19: Best year (total) | C19: =MAX(D2:D10) -> 0.5801
A20: Worst year (total) | C20: =MIN(D2:D10) -> -0.4269
A21: Standard deviation of annual returns | C21: =STDEV(D2:D10) -> 0.34120698
A22: $1 grew to (total, 2017-2025) | C22: =H10 -> 2.5140892
A23: S&P 500 (SPY) average annual total return | C23: =AVERAGE(J2:J10) -> 0.16225556
A24: S&P 500 (SPY) CAGR, same years | C24: =EXP(SUMPRODUCT(LN(1+J2:J10)))^(1/COUNT(J2:J10))-1 -> 0.15021574
A25: S&P 500 (SPY) $1 grew to | C25: =EXP(SUMPRODUCT(LN(1+J2:J10))) -> 3.5238204
A26: S&P 500 (SPY) standard deviation | C26: =STDEV(J2:J10) -> 0.16614364
A28: Fund returns from Yahoo Finance daily data (last trading day of each year). Total return reinvests distributions. Real returns are CPI-adjusted. 'Average' is the simple mean; 'Annualized / CAGR' is the compound rate actually earned.
A29: 2016 (launch year, partial) and 2026 (incomplete) are excluded. See the Notes tab.

Sheet By Decade
A1: Decade | B1: Years Covered | C1: # of Years | D1: Up Years | E1: Down Years | F1: Avg Annual Total Return | G1: Annualized (CAGR) Total Return | H1: Cumulative Total Return | I1: Avg Annual Price Return | J1: Annualized (CAGR) Price Return | K1: Avg Annual Real Total Return | L1: Best Year (Total) | M1: Worst Year (Total) | N1: $1 Grew To (Total) | O1: S&P 500 (SPY) CAGR, same years
A2: 2010s | B2: 2017–2019 (partial) | C2: =COUNTIF('Annual Returns'!$B$2:$B$10,"2010s") -> 3 | D2: =COUNTIFS('Annual Returns'!$B$2:$B$10,"2010s",'Annual Returns'!$D$2:$D$10,">=0") -> 2 | E2: =COUNTIFS('Annual Returns'!$B$2:$B$10,"2010s",'Annual Returns'!$D$2:$D$10,"<0") -> 1 | F2: =AVERAGEIF('Annual Returns'!$B$2:$B$10,"2010s",'Annual Returns'!$D$2:$D$10) -> 0.2049 | G2: =(1+H2)^(1/C2)-1 -> 0.14277026 | H2: =EXP(SUMPRODUCT(('Annual Returns'!$B$2:$B$10="2010s")*LN(1+'Annual Returns'!$D$2:$D$10)))-1 -> 0.49237095 | I2: =AVERAGEIF('Annual Returns'!$B$2:$B$10,"2010s",'Annual Returns'!$C$2:$C$10) -> 0.1976 | J2: =(EXP(SUMPRODUCT(('Annual Returns'!$B$2:$B$10="2010s")*LN(1+'Annual Returns'!$C$2:$C$10))))^(1/C2)-1 -> 0.13392736 | K2: =AVERAGEIF('Annual Returns'!$B$2:$B$10,"2010s",'Annual Returns'!$F$2:$F$10) -> 0.17973333 | L2: =_xlfn.MAXIFS('Annual Returns'!$D$2:$D$10,'Annual Returns'!$B$2:$B$10,"2010s") -> 0.5801 | M2: =_xlfn.MINIFS('Annual Returns'!$D$2:$D$10,'Annual Returns'!$B$2:$B$10,"2010s") -> -0.2834 | N2: =1+H2 -> 1.492371 | O2: =(EXP(SUMPRODUCT(('Annual Returns'!$B$2:$B$10="2010s")*LN(1+'Annual Returns'!$J$2:$J$10))))^(1/C2)-1 -> 0.1508103
A3: 2020s | B3: 2020–2025 (partial) | C3: =COUNTIF('Annual Returns'!$B$2:$B$10,"2020s") -> 6 | D3: =COUNTIFS('Annual Returns'!$B$2:$B$10,"2020s",'Annual Returns'!$D$2:$D$10,">=0") -> 5 | E3: =COUNTIFS('Annual Returns'!$B$2:$B$10,"2020s",'Annual Returns'!$D$2:$D$10,"<0") -> 1 | F3: =AVERAGEIF('Annual Returns'!$B$2:$B$10,"2020s",'Annual Returns'!$D$2:$D$10) -> 0.13876667 | G3: =(1+H3)^(1/C3)-1 -> 0.090813864 | H3: =EXP(SUMPRODUCT(('Annual Returns'!$B$2:$B$10="2020s")*LN(1+'Annual Returns'!$D$2:$D$10)))-1 -> 0.68462753 | I3: =AVERAGEIF('Annual Returns'!$B$2:$B$10,"2020s",'Annual Returns'!$C$2:$C$10) -> 0.1356 | J3: =(EXP(SUMPRODUCT(('Annual Returns'!$B$2:$B$10="2020s")*LN(1+'Annual Returns'!$C$2:$C$10))))^(1/C3)-1 -> 0.087801385 | K3: =AVERAGEIF('Annual Returns'!$B$2:$B$10,"2020s",'Annual Returns'!$F$2:$F$10) -> 0.09995 | L3: =_xlfn.MAXIFS('Annual Returns'!$D$2:$D$10,'Annual Returns'!$B$2:$B$10,"2020s") -> 0.5192 | M3: =_xlfn.MINIFS('Annual Returns'!$D$2:$D$10,'Annual Returns'!$B$2:$B$10,"2020s") -> -0.4269 | N3: =1+H3 -> 1.6846275 | O3: =(EXP(SUMPRODUCT(('Annual Returns'!$B$2:$B$10="2020s")*LN(1+'Annual Returns'!$J$2:$J$10))))^(1/C3)-1 -> 0.14991858
A4: All years | B4: 2017–2025 | C4: =COUNT('Annual Returns'!$A$2:$A$10) -> 9 | D4: =COUNTIF('Annual Returns'!$D$2:$D$10,">=0") -> 7 | E4: =COUNTIF('Annual Returns'!$D$2:$D$10,"<0") -> 2 | F4: =AVERAGE('Annual Returns'!$D$2:$D$10) -> 0.16081111 | G4: =(1+H4)^(1/C4)-1 -> 0.10786475 | H4: =EXP(SUMPRODUCT(LN(1+'Annual Returns'!$D$2:$D$10)))-1 -> 1.5140892 | I4: =AVERAGE('Annual Returns'!$C$2:$C$10) -> 0.15626667 | J4: =(EXP(SUMPRODUCT(LN(1+'Annual Returns'!$C$2:$C$10))))^(1/C4)-1 -> 0.10296437 | K4: =AVERAGE('Annual Returns'!$F$2:$F$10) -> 0.12654444 | L4: =MAX('Annual Returns'!$D$2:$D$10) -> 0.5801 | M4: =MIN('Annual Returns'!$D$2:$D$10) -> -0.4269 | N4: =1+H4 -> 2.5140892 | O4: =(EXP(SUMPRODUCT(LN(1+'Annual Returns'!$J$2:$J$10))))^(1/C4)-1 -> 0.15021574
A7: Decades are calendar decades; partial decades are marked.
A8: Avg Annual = simple average of the yearly returns. Annualized (CAGR) = the compound rate that turns the starting dollar into the ending dollar.
A9: All figures pull live from the 'Annual Returns' tab. Source and methodology: see the Notes tab.
